Workbook
Name a: #REF!

Sheet 1. Raw Data
A1: CustomerID | B1: Age | C1: Gender | D1: Tenure | E1: MonthlyCharges | F1: ContractType | G1: PaymentMethod | H1: SupportTickets | I1: ServiceUsage | J1: SatisfactionScore | K1: TotalSpend | L1: Churn | M1: No Churn | N1: Churn | Q1: ContractType | R1: Churn
A2: 1 | B2: 56 | C2: Female | D2: 58 | E2: 28.27 | F2: 1-Year | G2: Credit Card | H2: 2 | I2: 52.7 | J2: 6 | K2: 1614.09 | L2: 1 | M2: =COUNTIF(L2:L251, 0) -> 132 | N2: =COUNTIF(L2:L251, 1) -> 118 | O2: =N2/250 -> 0.472 | Q2: 1-Year | R2: 1
A3: 2 | B3: 69 | C3: Female | D3: 63 | E3: 107.67 | F3: 1-Year | G3: Credit Card | H3: 1 | I3: 16.8 | J3: 1 | K3: 6505.15 | L3: 1 | Q3: 1-Year | R3: 1
A4: 3 | B4: 46 | C4: Female | D4: 62 | E4: 75.16 | F4: Month-to-Month | G4: Bank Transfer | H4: 1 | I4: 41.6 | J4: 5 | K4: 4646.87 | L4: 0 | Q4: Month-to-Month | R4: 0
A5: 4 | B5: 32 | C5: Male | D5: 22 | E5: 36.48 | F5: Month-to-Month | G5: PayPal | H5: 1 | I5: 66.1 | J5: 3 | K5: 814.95 | L5: 1 | Q5: Month-to-Month | R5: 1
A6: 5 | B6: 60 | C6: Male | D6: 58 | E6: 61.13 | F6: 1-Year | G6: Bank Transfer | H6: 3 | I6: 79.1 | J6: 1 | K6: 3222 | L6: 1 | Q6: 1-Year | R6: 1
A7: 6 | B7: 25 | C7: Female | D7: 58 | E7: 97.76 | F7: Month-to-Month | G7: PayPal | H7: 2 | I7: 25.6 | J7: 4 | K7: 5242.56 | L7: 1 | Q7: Month-to-Month | R7: 1
A8: 7 | B8: 38 | C8: Female | D8: 49 | E8: 68.04 | F8: 1-Year | G8: Credit Card | H8: 2 | I8: 18.1 | J8: 2 | K8: 3373.06 | L8: 1 | Q8: 1-Year | R8: 1
A9: 8 | B9: 56 | C9: Male | D9: 52 | E9: 118.53 | F9: Month-to-Month | G9: PayPal | H9: 3 | I9: 68 | J9: 2 | K9: 5970.23 | L9: 0 | Q9: Month-to-Month | R9: 0
A10: 9 | B10: 36 | C10: Male | D10: 42 | E10: 57.67 | F10: Month-to-Month | G10: Bank Transfer | H10: 0 | I10: 5.2 | J10: 3 | K10: 2533.16 | L10: 1 | Q10: Month-to-Month | R10: 1
A11: 10 | B11: 40 | C11: Female | D11: 70 | E11: 94.96 | F11: Month-to-Month | G11: Credit Card | H11: 5 | I11: 21.9 | J11: 8 | K11: 6849.66 | L11: 0 | Q11: Month-to-Month | R11: 0
A12: 11 | B12: 28 | C12: Male | D12: 15 | E12: 59.3 | F12: Month-to-Month | G12: Bank Transfer | H12: 1 | I12: 7.8 | J12: 8 | K12: 950.98 | L12: 0 | Q12: Month-to-Month | R12: 0
A13: 12 | B13: 28 | C13: Female | D13: 54 | E13: 102.92 | F13: 1-Year | G13: Bank Transfer | H13: 3 | I13: 20.9 | J13: 7 | K13: 5771.64 | L13: 0 | Q13: 1-Year | R13: 0
A14: 13 | B14: 41 | C14: Female | D14: 60 | E14: 76.91 | F14: Month-to-Month | G14: PayPal | H14: 0 | I14: 22.2 | J14: 6 | K14: 4549.93 | L14: 0 | Q14: Month-to-Month | R14: 0
... A251: 250 | B251: 69 | C251: Male | D251: 66 | E251: 95.24 | F251: 1-Year | G251: Bank Transfer | H251: 5 | I251: 46.4 | J251: 9 | K251: 6712.45 | L251: 0 | Q251: 1-Year | R251: 0

Sheet 2. Descriptive
B1: min | C1: Q1 (lower hinge) | D1: Median (mid-hinge) | E1: Q3 (upper hinge) | F1: max | G1: SIQR
A2: Age | B2: =MIN('1. Raw Data'!B2:B251) -> 18 | C2: =_xlfn.QUARTILE.INC('1. Raw Data'!B2:B251, 1) -> 31 | D2: =MEDIAN('1. Raw Data'!B2:B251) -> 44 | E2: =_xlfn.QUARTILE.INC('1. Raw Data'!B2:B251, 3) -> 56 | F2: =MAX('1. Raw Data'!B2:B251) -> 69 | G2: =(E2-C2)/2 -> 12.5
A3: Tenure | B3: =MIN('1. Raw Data'!D2:D251) -> 1 | C3: =_xlfn.QUARTILE.INC('1. Raw Data'!D2:D251, 1) -> 17 | D3: =MEDIAN('1. Raw Data'!D2:D251) -> 35.5 | E3: =_xlfn.QUARTILE.INC('1. Raw Data'!D2:D251, 3) -> 55 | F3: =MAX('1. Raw Data'!D2:D251) -> 71 | G3: =(E3-C3)/2 -> 19
A4: MonthlyCharges | B4: =MIN('1. Raw Data'!E2:E251) -> 20.26 | C4: =_xlfn.QUARTILE.INC('1. Raw Data'!E2:E251, 1) -> 50.99 | D4: =MEDIAN('1. Raw Data'!E2:E251) -> 73.595 | E4: =_xlfn.QUARTILE.INC('1. Raw Data'!E2:E251, 3) -> 94.87 | F4: =MAX('1. Raw Data'!E2:E251) -> 119.77 | G4: =(E4-C4)/2 -> 21.94
A5: SupportTickets | B5: =MIN('1. Raw Data'!H2:H251) -> 0 | C5: =_xlfn.QUARTILE.INC('1. Raw Data'!H2:H251, 1) -> 1 | D5: =MEDIAN('1. Raw Data'!H2:H251) -> 2 | E5: =_xlfn.QUARTILE.INC('1. Raw Data'!H2:H251, 3) -> 3 | F5: =MAX('1. Raw Data'!H2:H251) -> 6 | G5: =(E5-C5)/2 -> 1
A6: ServiceUsage | B6: =MIN('1. Raw Data'!I2:I251) -> 5.2 | C6: =_xlfn.QUARTILE.INC('1. Raw Data'!I2:I251, 1) -> 26.4 | D6: =MEDIAN('1. Raw Data'!I2:I251) -> 50.9 | E6: =_xlfn.QUARTILE.INC('1. Raw Data'!I2:I251, 3) -> 75.75 | F6: =MAX('1. Raw Data'!I2:I251) -> 99.7 | G6: =(E6-C6)/2 -> 24.675
A7: SatisfactionScore | B7: =MIN('1. Raw Data'!J2:J251) -> 1 | C7: =_xlfn.QUARTILE.INC('1. Raw Data'!J2:J251, 1) -> 3 | D7: =MEDIAN('1. Raw Data'!J2:J251) -> 5 | E7: =_xlfn.QUARTILE.INC('1. Raw Data'!J2:J251, 3) -> 8 | F7: =MAX('1. Raw Data'!J2:J251) -> 10 | G7: =(E7-C7)/2 -> 2.5
A8: TotalSpend | B8: =MIN('1. Raw Data'!K2:K251) -> 35.73 | C8: =_xlfn.QUARTILE.INC('1. Raw Data'!K2:K251, 1) -> 1036.0825 | D8: =MEDIAN('1. Raw Data'!K2:K251) -> 2057.21 | E8: =_xlfn.QUARTILE.INC('1. Raw Data'!K2:K251, 3) -> 3759.65 | F8: =MAX('1. Raw Data'!K2:K251) -> 7782.69 | G8: =(E8-C8)/2 -> 1361.7838
A14: Metric | C14: Age | D14: Tenure | E14: MonthlyCharges | F14: SupportTickets | G14: ServiceUsage | H14: SaticsfactionScore | I14: TotalSpend
A15: Count | B15: NoChurn | C15: 132 | D15: 132 | E15: 132 | F15: 132 | G15: 132 | H15: 132 | I15: 132
B16: Churn | C16: 118 | D16: 118 | E16: 118 | F16: 118 | G16: 118 | H16: 118 | I16: 118
A17: min | B17: NoChurn | C17: ='2.28 FiveNumber_Churn0'!B2 -> 18 | D17: ='2.28 FiveNumber_Churn0'!B3 -> 1 | E17: ='2.28 FiveNumber_Churn0'!B4 -> 20.26 | F17: ='2.28 FiveNumber_Churn0'!B5 -> 0 | G17: ='2.28 FiveNumber_Churn0'!B6 -> 5.2 | H17: ='2.28 FiveNumber_Churn0'!B7 -> 1 | I17: ='2.28 FiveNumber_Churn0'!B8 -> 35.73
B18: Churn | C18: ='2.29 FiveNumber_Churn1'!B2 -> 18 | D18: ='2.29 FiveNumber_Churn1'!B3 -> 1 | E18: ='2.29 FiveNumber_Churn1'!B4 -> 20.53 | F18: ='2.29 FiveNumber_Churn1'!B5 -> 0 | G18: ='2.29 FiveNumber_Churn1'!B6 -> 5.2 | H18: ='2.29 FiveNumber_Churn1'!B7 -> 1 | I18: ='2.29 FiveNumber_Churn1'!B8 -> 105.78
A19: Q1 | B19: NoChurn | C19: ='2.28 FiveNumber_Churn0'!C2 -> 29.75 | D19: ='2.28 FiveNumber_Churn0'!C3 -> 17 | E19: ='2.28 FiveNumber_Churn0'!C4 -> 53 | F19: ='2.28 FiveNumber_Churn0'!C5 -> 1 | G19: ='2.28 FiveNumber_Churn0'!C6 -> 23.5 | H19: ='2.28 FiveNumber_Churn0'!C7 -> 4 | I19: ='2.28 FiveNumber_Churn0'!C8 -> 1121.1375
B20: Churn | C20: ='2.29 FiveNumber_Churn1'!C2 -> 32 | D20: ='2.29 FiveNumber_Churn1'!C3 -> 17.25 | E20: ='2.29 FiveNumber_Churn1'!C4 -> 48.5075 | F20: ='2.29 FiveNumber_Churn1'!C5 -> 1 | G20: ='2.29 FiveNumber_Churn1'!C6 -> 27.6 | H20: ='2.29 FiveNumber_Churn1'!C7 -> 2 | I20: ='2.29 FiveNumber_Churn1'!C8 -> 921.27
A21: Median | B21: NoChurn | C21: ='2.28 FiveNumber_Churn0'!D2 -> 45 | D21: ='2.28 FiveNumber_Churn0'!D3 -> 39.5 | E21: ='2.28 FiveNumber_Churn0'!D4 -> 73.58 | F21: ='2.28 FiveNumber_Churn0'!D5 -> 2 | G21: ='2.28 FiveNumber_Churn0'!D6 -> 44.8 | H21: ='2.28 FiveNumber_Churn0'!D7 -> 6 | I21: ='2.28 FiveNumber_Churn0'!D8 -> 2197.935
B22: Churn | C22: ='2.29 FiveNumber_Churn1'!D2 -> 43 | D22: ='2.29 FiveNumber_Churn1'!D3 -> 33.5 | E22: ='2.29 FiveNumber_Churn1'!D4 -> 73.63 | F22: ='2.29 FiveNumber_Churn1'!D5 -> 2 | G22: ='2.29 FiveNumber_Churn1'!D6 -> 57.75 | H22: ='2.29 FiveNumber_Churn1'!D7 -> 4 | I22: ='2.29 FiveNumber_Churn1'!D8 -> 1943.275
A23: Mean | B23: NoChurn | C23: =AVERAGE('2.25 Churn0 '!B2:B133) -> 43.916667 | D23: =AVERAGE('2.25 Churn0 '!D2:D133) -> 37.818182 | E23: =AVERAGE('2.25 Churn0 '!E2:E133) -> 71.76947 | F23: =AVERAGE('2.25 Churn0 '!H2:H133) -> 2.0151515 | G23: =AVERAGE('2.25 Churn0 '!I2:I133) -> 48.489394 | H23: =AVERAGE('2.25 Churn0 '!J2:J133) -> 6.0151515 | I23: =AVERAGE('2.25 Churn0 '!K2:K133) -> 2752.1336
B24: Churn | C24: =AVERAGE('2.26 Churn1'!B2:B119) -> 43.152542 | D24: =AVERAGE('2.26 Churn1'!D2:D119) -> 33.694915 | E24: =AVERAGE('2.26 Churn1'!E2:E119) -> 70.934407 | F24: =AVERAGE('2.26 Churn1'!H2:H119) -> 1.9067797 | G24: =AVERAGE('2.26 Churn1'!I2:I119) -> 54.710169 | H24: =AVERAGE('2.26 Churn1'!J2:J119) -> 4.5677966 | I24: =AVERAGE('2.26 Churn1'!K2:K119) -> 2328.622
A25: Q3 | B25: NoChurn | C25: ='2.28 FiveNumber_Churn0'!E2 -> 57 | D25: ='2.28 FiveNumber_Churn0'!E3 -> 57.25 | E25: ='2.28 FiveNumber_Churn0'!E4 -> 93.695 | F25: ='2.28 FiveNumber_Churn0'!E5 -> 3 | G25: ='2.28 FiveNumber_Churn0'!E6 -> 73.475 | H25: ='2.28 FiveNumber_Churn0'!E7 -> 8 | I25: ='2.28 FiveNumber_Churn0'!E8 -> 4159.16
B26: Churn | C26: ='2.29 FiveNumber_Churn1'!E2 -> 55.75 | D26: ='2.29 FiveNumber_Churn1'!E3 -> 49 | E26: ='2.29 FiveNumber_Churn1'!E4 -> 95.7625 | F26: ='2.29 FiveNumber_Churn1'!E5 -> 3 | G26: ='2.29 FiveNumber_Churn1'!E6 -> 79.8 | H26: ='2.29 FiveNumber_Churn1'!E7 -> 7 | I26: ='2.29 FiveNumber_Churn1'!E8 -> 3214.915
A27: max | B27: NoChurn | C27: ='2.28 FiveNumber_Churn0'!F2 -> 69 | D27: ='2.28 FiveNumber_Churn0'!F3 -> 71 | E27: ='2.28 FiveNumber_Churn0'!F4 -> 118.63 | F27: ='2.28 FiveNumber_Churn0'!F5 -> 5 | G27: ='2.28 FiveNumber_Churn0'!F6 -> 99.2 | H27: ='2.28 FiveNumber_Churn0'!F7 -> 10 | I27: ='2.28 FiveNumber_Churn0'!F8 -> 7782.69
B28: Churn | C28: ='2.29 FiveNumber_Churn1'!F2 -> 69 | D28: ='2.29 FiveNumber_Churn1'!F3 -> 71 | E28: ='2.29 FiveNumber_Churn1'!F4 -> 119.77 | F28: ='2.29 FiveNumber_Churn1'!F5 -> 6 | G28: ='2.29 FiveNumber_Churn1'!F6 -> 99.7 | H28: ='2.29 FiveNumber_Churn1'!F7 -> 10 | I28: ='2.29 FiveNumber_Churn1'!F8 -> 7426.03
A29: SIQR | B29: NoChurn | C29: ='2.28 FiveNumber_Churn0'!G2 -> 13.625 | D29: ='2.28 FiveNumber_Churn0'!G3 -> 20.125 | E29: ='2.28 FiveNumber_Churn0'!G4 -> 20.3475 | F29: ='2.28 FiveNumber_Churn0'!G5 -> 1 | G29: ='2.28 FiveNumber_Churn0'!G6 -> 24.9875 | H29: ='2.28 FiveNumber_Churn0'!G7 -> 2 | I29: ='2.28 FiveNumber_Churn0'!G8 -> 1519.0113
B30: Churn | C30: ='2.29 FiveNumber_Churn1'!G2 -> 11.875 | D30: ='2.29 FiveNumber_Churn1'!G3 -> 15.875 | E30: ='2.29 FiveNumber_Churn1'!G4 -> 23.6275 | F30: ='2.29 FiveNumber_Churn1'!G5 -> 1 | G30: ='2.29 FiveNumber_Churn1'!G6 -> 26.1 | H30: ='2.29 FiveNumber_Churn1'!G7 -> 2.5 | I30: ='2.29 FiveNumber_Churn1'!G8 -> 1146.8225
A31: std | B31: NoChurn | C31: =_xlfn.STDEV.S('2.25 Churn0 '!B2:B133) -> 15.597534 | D31: =_xlfn.STDEV.S('2.25 Churn0 '!D2:D133) -> 21.048769 | E31: =_xlfn.STDEV.S('2.25 Churn0 '!E2:E133) -> 27.599024 | F31: =_xlfn.STDEV.S('2.25 Churn0 '!H2:H133) -> 1.3978438 | G31: =_xlfn.STDEV.S('2.25 Churn0 '!I2:I133) -> 26.954973 | H31: =_xlfn.STDEV.S('2.25 Churn0 '!J2:J133) -> 2.6471498 | I31: =_xlfn.STDEV.S('2.25 Churn0 '!K2:K133) -> 1965.8209
B32: Churn | C32: =_xlfn.STDEV.S('2.26 Churn1'!B2:B119) -> 15.031947 | D32: =_xlfn.STDEV.S('2.26 Churn1'!D2:D119) -> 19.931296 | E32: =_xlfn.STDEV.S('2.26 Churn1'!E2:E119) -> 28.62834 | F32: =_xlfn.STDEV.S('2.26 Churn1'!H2:H119) -> 1.3460121 | G32: =_xlfn.STDEV.S('2.26 Churn1'!I2:I119) -> 28.599705 | H32: =_xlfn.STDEV.S('2.26 Churn1'!J2:J119) -> 2.8569268 | I32: =_xlfn.STDEV.S('2.26 Churn1'!K2:K119) -> 1696.9013

Sheet 3. Predictive
A1: CustomerID | B1: Age | C1: Gender | D1: Tenure | E1: MonthlyCharges | F1: ContractType | G1: PaymentMethod | H1: SupportTickets | I1: ServiceUsage | J1: SatisfactionScore | K1: TotalSpend | L1: Churn | M1: Split | N1: Tenure_Bin | O1: Monthly_Bin | P1: Satis_Bin | Q1: Usage_Bin | R1: Contract_Key | S1: Tenure_Key | T1: Satis_Key | U1: Monthly_Key | V1: Usage_Key | W1: Contract_Pts | X1: Tenure_Pts | Y1: Satis_Pts | Z1: Monthly_Pts | AA1: Usage_Pts | AB1: TotalScore | AC1: PredictedClass | AD1: PredictedChurn | AE1: PredFlag | AF1: PredictedProb | AG1: PredictedChurn | AH1: RiskTier | AI1: Customer Risk List | AJ1: RiskRank | AK1: Thresholds | AN1: Key | AO1: Score
A2: 1 | B2: 56 | C2: Female | D2: 58 | E2: 28.27 | F2: 1-Year | G2: Credit Card | H2: 2 | I2: 52.7 | J2: 6 | K2: 1614.09 | L2: 1 | M2: Test | N2: =IF(D2<6,"<6", IF(D2<12,"6-12", IF(D2<24,"12-24",">=24"))) -> >=24 | O2: =IF(E2<30,"<30", IF(E2<60,"30-60", IF(E2<90,"60-90",">=90"))) -> <30 | P2: =IF(J2<4,"1-3", IF(J2<7,"4-6","7-10")) -> 4-6 | Q2: =IF(I2<20,"<20", IF(I2<40,"20-40", IF(I2<80,"40-80",">=80"))) -> 40-80 | R2: ="ContractType|"&F2 -> ContractType|1-Year | S2: ="Tenure_Bin|"&N2 -> Tenure_Bin|>=24 | T2: ="Satis_Bin|"&P2 -> Satis_Bin|4-6 | U2: ="Monthly_Bin|"&O2 -> Monthly_Bin|<30 | V2: ="Usage_Bin|"&Q2 -> Usage_Bin|40-80 | W2: =_xlfn.XLOOKUP(R2,$AN$2:$AN$19,$AO$2:$AO$19,0) -> 1 | X2: =_xlfn.XLOOKUP(N2,$AN$2:$AN$19,$AO$2:$AO$19,0) -> 0 | Y2: =_xlfn.XLOOKUP(P2,$AN$2:$AN$19,$AO$2:$AO$19,0) -> 2 | Z2: =_xlfn.XLOOKUP(O2,$AN$2:$AN$19,$AO$2:$AO$19,0) -> 0 | AA2: =_xlfn.XLOOKUP(Q2,$AN$2:$AN$19,$AO$2:$AO$19,0) -> 0 | AB2: =SUM(W2:AA2) -> 3 | AC2: =IF(AB2>=7,"High", IF(AB2>=4,"Medium","Low")) -> Low | AD2: =IF(AB2>=$AK$2,"Yes","No") -> No | AE2: =IF(AD2="Yes",1,0) -> 0 | AF2: =_xlfn.XLOOKUP(AB2, '3.3 Calibration'!$A$2:$A$14, '3.3 Calibration'!$F$2:$F$14, '3.3 Calibration'!$D$2, 1) -> 0.42105263 | AG2: =IF(AF2 >= 0.5, "Yes", "No") -> No | AH2: =IF(AF2>=0.6,"High", IF(AF2>=0.4,"Medium","Low")) -> Medium | AI2: =IF(AH2="High",N2,NA()) -> #N/A | AJ2: =_xlfn.RANK.EQ(AF2, AF:AF, 0) -> 117 | AK2: 13 | AL2: 0.5 | AN2: ContractType|Month-to-Month | AO2: 3
A3: 2 | B3: 69 | C3: Female | D3: 63 | E3: 107.67 | F3: 1-Year | G3: Credit Card | H3: 1 | I3: 16.8 | J3: 1 | K3: 6505.15 | L3: 1 | M3: Train | N3: =IF(D3<6,"<6", IF(D3<12,"6-12", IF(D3<24,"12-24",">=24"))) -> >=24 | O3: =IF(E3<30,"<30", IF(E3<60,"30-60", IF(E3<90,"60-90",">=90"))) -> >=90 | P3: =IF(J3<4,"1-3", IF(J3<7,"4-6","7-10")) -> 1-3 | Q3: =IF(I3<20,"<20", IF(I3<40,"20-40", IF(I3<80,"40-80",">=80"))) -> <20 | R3: ="ContractType|"&F3 -> ContractType|1-Year | S3: ="Tenure_Bin|"&N3 -> Tenure_Bin|>=24 | T3: ="Satis_Bin|"&P3 -> Satis_Bin|1-3 | U3: ="Monthly_Bin|"&O3 -> Monthly_Bin|>=90 | V3: ="Usage_Bin|"&Q3 -> Usage_Bin|<20 | W3: =_xlfn.XLOOKUP(R3,$AN$2:$AN$19,$AO$2:$AO$19,0) -> 1 | X3: =_xlfn.XLOOKUP(N3,$AN$2:$AN$19,$AO$2:$AO$19,0) -> 0 | Y3: =_xlfn.XLOOKUP(P3,$AN$2:$AN$19,$AO$2:$AO$19,0) -> 4 | Z3: =_xlfn.XLOOKUP(O3,$AN$2:$AN$19,$AO$2:$AO$19,0) -> 2 | AA3: =_xlfn.XLOOKUP(Q3,$AN$2:$AN$19,$AO$2:$AO$19,0) -> 2 | AB3: =SUM(W3:AA3) -> 9 | AC3: =IF(AB3>=7,"High", IF(AB3>=4,"Medium","Low")) -> High | AD3: =IF(AB3>=$AK$2,"Yes","No") -> No | AE3: =IF(AD3="Yes",1,0) -> 0 | AF3: =_xlfn.XLOOKUP(AB3, '3.3 Calibration'!$A$2:$A$14, '3.3 Calibration'!$F$2:$F$14, '3.3 Calibration'!$D$2, 1) -> 0.54545455 | AG3: =IF(AF3 >= 0.5, "Yes", "No") -> Yes | AH3: =IF(AF3>=0.6,"High", IF(AF3>=0.4,"Medium","Low")) -> Medium | AI3: =IF(AH3="High",N3,NA()) -> #N/A | AN3: ContractType|1-Year | AO3: 1
A4: 3 | B4: 46 | C4: Female | D4: 62 | E4: 75.16 | F4: Month-to-Month | G4: Bank Transfer | H4: 1 | I4: 41.6 | J4: 5 | K4: 4646.87 | L4: 0 | M4: Test | N4: =IF(D4<6,"<6", IF(D4<12,"6-12", IF(D4<24,"12-24",">=24"))) -> >=24 | O4: =IF(E4<30,"<30", IF(E4<60,"30-60", IF(E4<90,"60-90",">=90"))) -> 60-90 | P4: =IF(J4<4,"1-3", IF(J4<7,"4-6","7-10")) -> 4-6 | Q4: =IF(I4<20,"<20", IF(I4<40,"20-40", IF(I4<80,"40-80",">=80"))) -> 40-80 | R4: ="ContractType|"&F4 -> ContractType|Month-to-Month | S4: ="Tenure_Bin|"&N4 -> Tenure_Bin|>=24 | T4: ="Satis_Bin|"&P4 -> Satis_Bin|4-6 | U4: ="Monthly_Bin|"&O4 -> Monthly_Bin|60-90 | V4: ="Usage_Bin|"&Q4 -> Usage_Bin|40-80 | W4: =_xlfn.XLOOKUP(R4,$AN$2:$AN$19,$AO$2:$AO$19,0) -> 3 | X4: =_xlfn.XLOOKUP(N4,$AN$2:$AN$19,$AO$2:$AO$19,0) -> 0 | Y4: =_xlfn.XLOOKUP(P4,$AN$2:$AN$19,$AO$2:$AO$19,0) -> 2 | Z4: =_xlfn.XLOOKUP(O4,$AN$2:$AN$19,$AO$2:$AO$19,0) -> 1 | AA4: =_xlfn.XLOOKUP(Q4,$AN$2:$AN$19,$AO$2:$AO$19,0) -> 0 | AB4: =SUM(W4:AA4) -> 6 | AC4: =IF(AB4>=7,"High", IF(AB4>=4,"Medium","Low")) -> Medium | AD4: =IF(AB4>=$AK$2,"Yes","No") -> No | AE4: =IF(AD4="Yes",1,0) -> 0 | AF4: =_xlfn.XLOOKUP(AB4, '3.3 Calibration'!$A$2:$A$14, '3.3 Calibration'!$F$2:$F$14, '3.3 Calibration'!$D$2, 1) -> 0.33333333 | AG4: =IF(AF4 >= 0.5, "Yes", "No") -> No | AH4: =IF(AF4>=0.6,"High", IF(AF4>=0.4,"Medium","Low")) -> Low | AI4: =IF(AH4="High",N4,NA()) -> #N/A | AN4: ContractType|2-Year | AO4: 0
A5: 4 | B5: 32 | C5: Male | D5: 22 | E5: 36.48 | F5: Month-to-Month | G5: PayPal | H5: 1 | I5: 66.1 | J5: 3 | K5: 814.95 | L5: 1 | M5: Train | N5: =IF(D5<6,"<6", IF(D5<12,"6-12", IF(D5<24,"12-24",">=24"))) -> 12-24 | O5: =IF(E5<30,"<30", IF(E5<60,"30-60", IF(E5<90,"60-90",">=90"))) -> 30-60 | P5: =IF(J5<4,"1-3", IF(J5<7,"4-6","7-10")) -> 1-3 | Q5: =IF(I5<20,"<20", IF(I5<40,"20-40", IF(I5<80,"40-80",">=80"))) -> 40-80 | R5: ="ContractType|"&F5 -> ContractType|Month-to-Month | S5: ="Tenure_Bin|"&N5 -> Tenure_Bin|12-24 | T5: ="Satis_Bin|"&P5 -> Satis_Bin|1-3 | U5: ="Monthly_Bin|"&O5 -> Monthly_Bin|30-60 | V5: ="Usage_Bin|"&Q5 -> Usage_Bin|40-80 | W5: =_xlfn.XLOOKUP(R5,$AN$2:$AN$19,$AO$2:$AO$19,0) -> 3 | X5: =_xlfn.XLOOKUP(N5,$AN$2:$AN$19,$AO$2:$AO$19,0) -> 1 | Y5: =_xlfn.XLOOKUP(P5,$AN$2:$AN$19,$AO$2:$AO$19,0) -> 4 | Z5: =_xlfn.XLOOKUP(O5,$AN$2:$AN$19,$AO$2:$AO$19,0) -> 0 | AA5: =_xlfn.XLOOKUP(Q5,$AN$2:$AN$19,$AO$2:$AO$19,0) -> 0 | AB5: =SUM(W5:AA5) -> 8 | AC5: =IF(AB5>=7,"High", IF(AB5>=4,"Medium","Low")) -> High | AD5: =IF(AB5>=$AK$2,"Yes","No") -> No | AE5: =IF(AD5="Yes",1,0) -> 0 | AF5: =_xlfn.XLOOKUP(AB5, '3.3 Calibration'!$A$2:$A$14, '3.3 Calibration'!$F$2:$F$14, '3.3 Calibration'!$D$2, 1) -> 0.73684211 | AG5: =IF(AF5 >= 0.5, "Yes", "No") -> Yes | AH5: =IF(AF5>=0.6,"High", IF(AF5>=0.4,"Medium","Low")) -> High | AI5: =IF(AH5="High",N5,NA()) -> 12-24 | AN5: <6 | AO5: 3
A6: 5 | B6: 60 | C6: Male | D6: 58 | E6: 61.13 | F6: 1-Year | G6: Bank Transfer | H6: 3 | I6: 79.1 | J6: 1 | K6: 3222 | L6: 1 | M6: Train | N6: =IF(D6<6,"<6", IF(D6<12,"6-12", IF(D6<24,"12-24",">=24"))) -> >=24 | O6: =IF(E6<30,"<30", IF(E6<60,"30-60", IF(E6<90,"60-90",">=90"))) -> 60-90 | P6: =IF(J6<4,"1-3", IF(J6<7,"4-6","7-10")) -> 1-3 | Q6: =IF(I6<20,"<20", IF(I6<40,"20-40", IF(I6<80,"40-80",">=80"))) -> 40-80 | R6: ="ContractType|"&F6 -> ContractType|1-Year | S6: ="Tenure_Bin|"&N6 -> Tenure_Bin|>=24 | T6: ="Satis_Bin|"&P6 -> Satis_Bin|1-3 | U6: ="Monthly_Bin|"&O6 -> Monthly_Bin|60-90 | V6: ="Usage_Bin|"&Q6 -> Usage_Bin|40-80 | W6: =_xlfn.XLOOKUP(R6,$AN$2:$AN$19,$AO$2:$AO$19,0) -> 1 | X6: =_xlfn.XLOOKUP(N6,$AN$2:$AN$19,$AO$2:$AO$19,0) -> 0 | Y6: =_xlfn.XLOOKUP(P6,$AN$2:$AN$19,$AO$2:$AO$19,0) -> 4 | Z6: =_xlfn.XLOOKUP(O6,$AN$2:$AN$19,$AO$2:$AO$19,0) -> 1 | AA6: =_xlfn.XLOOKUP(Q6,$AN$2:$AN$19,$AO$2:$AO$19,0) -> 0 | AB6: =SUM(W6:AA6) -> 6 | AC6: =IF(AB6>=7,"High", IF(AB6>=4,"Medium","Low")) -> Medium | AD6: =IF(AB6>=$AK$2,"Yes","No") -> No | AE6: =IF(AD6="Yes",1,0) -> 0 | AF6: =_xlfn.XLOOKUP(AB6, '3.3 Calibration'!$A$2:$A$14, '3.3 Calibration'!$F$2:$F$14, '3.3 Calibration'!$D$2, 1) -> 0.33333333 | AG6: =IF(AF6 >= 0.5, "Yes", "No") -> No | AH6: =IF(AF6>=0.6,"High", IF(AF6>=0.4,"Medium","Low")) -> Low | AI6: =IF(AH6="High",N6,NA()) -> #N/A | AN6: 6-12 | AO6: 2
A7: 6 | B7: 25 | C7: Female | D7: 58 | E7: 97.76 | F7: Month-to-Month | G7: PayPal | H7: 2 | I7: 25.6 | J7: 4 | K7: 5242.56 | L7: 1 | M7: Train | N7: =IF(D7<6,"<6", IF(D7<12,"6-12", IF(D7<24,"12-24",">=24"))) -> >=24 | O7: =IF(E7<30,"<30", IF(E7<60,"30-60", IF(E7<90,"60-90",">=90"))) -> >=90 | P7: =IF(J7<4,"1-3", IF(J7<7,"4-6","7-10")) -> 4-6 | Q7: =IF(I7<20,"<20", IF(I7<40,"20-40", IF(I7<80,"40-80",">=80"))) -> 20-40 | R7: ="ContractType|"&F7 -> ContractType|Month-to-Month | S7: ="Tenure_Bin|"&N7 -> Tenure_Bin|>=24 | T7: ="Satis_Bin|"&P7 -> Satis_Bin|4-6 | U7: ="Monthly_Bin|"&O7 -> Monthly_Bin|>=90 | V7: ="Usage_Bin|"&Q7 -> Usage_Bin|20-40 | W7: =_xlfn.XLOOKUP(R7,$AN$2:$AN$19,$AO$2:$AO$19,0) -> 3 | X7: =_xlfn.XLOOKUP(N7,$AN$2:$AN$19,$AO$2:$AO$19,0) -> 0 | Y7: =_xlfn.XLOOKUP(P7,$AN$2:$AN$19,$AO$2:$AO$19,0) -> 2 | Z7: =_xlfn.XLOOKUP(O7,$AN$2:$AN$19,$AO$2:$AO$19,0) -> 2 | AA7: =_xlfn.XLOOKUP(Q7,$AN$2:$AN$19,$AO$2:$AO$19,0) -> 1 | AB7: =SUM(W7:AA7) -> 8 | AC7: =IF(AB7>=7,"High", IF(AB7>=4,"Medium","Low")) -> High | AD7: =IF(AB7>=$AK$2,"Yes","No") -> No | AE7: =IF(AD7="Yes",1,0) -> 0 | AF7: =_xlfn.XLOOKUP(AB7, '3.3 Calibration'!$A$2:$A$14, '3.3 Calibration'!$F$2:$F$14, '3.3 Calibration'!$D$2, 1) -> 0.73684211 | AG7: =IF(AF7 >= 0.5, "Yes", "No") -> Yes | AH7: =IF(AF7>=0.6,"High", IF(AF7>=0.4,"Medium","Low")) -> High | AI7: =IF(AH7="High",N7,NA()) -> >=24 | AN7: 12-24 | AO7: 1
A8: 7 | B8: 38 | C8: Female | D8: 49 | E8: 68.04 | F8: 1-Year | G8: Credit Card | H8: 2 | I8: 18.1 | J8: 2 | K8: 3373.06 | L8: 1 | M8: Test | N8: =IF(D8<6,"<6", IF(D8<12,"6-12", IF(D8<24,"12-24",">=24"))) -> >=24 | O8: =IF(E8<30,"<30", IF(E8<60,"30-60", IF(E8<90,"60-90",">=90"))) -> 60-90 | P8: =IF(J8<4,"1-3", IF(J8<7,"4-6","7-10")) -> 1-3 | Q8: =IF(I8<20,"<20", IF(I8<40,"20-40", IF(I8<80,"40-80",">=80"))) -> <20 | R8: ="ContractType|"&F8 -> ContractType|1-Year | S8: ="Tenure_Bin|"&N8 -> Tenure_Bin|>=24 | T8: ="Satis_Bin|"&P8 -> Satis_Bin|1-3 | U8: ="Monthly_Bin|"&O8 -> Monthly_Bin|60-90 | V8: ="Usage_Bin|"&Q8 -> Usage_Bin|<20 | W8: =_xlfn.XLOOKUP(R8,$AN$2:$AN$19,$AO$2:$AO$19,0) -> 1 | X8: =_xlfn.XLOOKUP(N8,$AN$2:$AN$19,$AO$2:$AO$19,0) -> 0 | Y8: =_xlfn.XLOOKUP(P8,$AN$2:$AN$19,$AO$2:$AO$19,0) -> 4 | Z8: =_xlfn.XLOOKUP(O8,$AN$2:$AN$19,$AO$2:$AO$19,0) -> 1 | AA8: =_xlfn.XLOOKUP(Q8,$AN$2:$AN$19,$AO$2:$AO$19,0) -> 2 | AB8: =SUM(W8:AA8) -> 8 | AC8: =IF(AB8>=7,"High", IF(AB8>=4,"Medium","Low")) -> High | AD8: =IF(AB8>=$AK$2,"Yes","No") -> No | AE8: =IF(AD8="Yes",1,0) -> 0 | AF8: =_xlfn.XLOOKUP(AB8, '3.3 Calibration'!$A$2:$A$14, '3.3 Calibration'!$F$2:$F$14, '3.3 Calibration'!$D$2, 1) -> 0.73684211 | AG8: =IF(AF8 >= 0.5, "Yes", "No") -> Yes | AH8: =IF(AF8>=0.6,"High", IF(AF8>=0.4,"Medium","Low")) -> High | AI8: =IF(AH8="High",N8,NA()) -> >=24 | AN8: >=24 | AO8: 0
A9: 8 | B9: 56 | C9: Male | D9: 52 | E9: 118.53 | F9: Month-to-Month | G9: PayPal | H9: 3 | I9: 68 | J9: 2 | K9: 5970.23 | L9: 0 | M9: Test | N9: =IF(D9<6,"<6", IF(D9<12,"6-12", IF(D9<24,"12-24",">=24"))) -> >=24 | O9: =IF(E9<30,"<30", IF(E9<60,"30-60", IF(E9<90,"60-90",">=90"))) -> >=90 | P9: =IF(J9<4,"1-3", IF(J9<7,"4-6","7-10")) -> 1-3 | Q9: =IF(I9<20,"<20", IF(I9<40,"20-40", IF(I9<80,"40-80",">=80"))) -> 40-80 | R9: ="ContractType|"&F9 -> ContractType|Month-to-Month | S9: ="Tenure_Bin|"&N9 -> Tenure_Bin|>=24 | T9: ="Satis_Bin|"&P9 -> Satis_Bin|1-3 | U9: ="Monthly_Bin|"&O9 -> Monthly_Bin|>=90 | V9: ="Usage_Bin|"&Q9 -> Usage_Bin|40-80 | W9: =_xlfn.XLOOKUP(R9,$AN$2:$AN$19,$AO$2:$AO$19,0) -> 3 | X9: =_xlfn.XLOOKUP(N9,$AN$2:$AN$19,$AO$2:$AO$19,0) -> 0 | Y9: =_xlfn.XLOOKUP(P9,$AN$2:$AN$19,$AO$2:$AO$19,0) -> 4 | Z9: =_xlfn.XLOOKUP(O9,$AN$2:$AN$19,$AO$2:$AO$19,0) -> 2 | AA9: =_xlfn.XLOOKUP(Q9,$AN$2:$AN$19,$AO$2:$AO$19,0) -> 0 | AB9: =SUM(W9:AA9) -> 9 | AC9: =IF(AB9>=7,"High", IF(AB9>=4,"Medium","Low")) -> High | AD9: =IF(AB9>=$AK$2,"Yes","No") -> No | AE9: =IF(AD9="Yes",1,0) -> 0 | AF9: =_xlfn.XLOOKUP(AB9, '3.3 Calibration'!$A$2:$A$14, '3.3 Calibration'!$F$2:$F$14, '3.3 Calibration'!$D$2, 1) -> 0.54545455 | AG9: =IF(AF9 >= 0.5, "Yes", "No") -> Yes | AH9: =IF(AF9>=0.6,"High", IF(AF9>=0.4,"Medium","Low")) -> Medium | AI9: =IF(AH9="High",N9,NA()) -> #N/A | AN9: 1-3 | AO9: 4
A10: 9 | B10: 36 | C10: Male | D10: 42 | E10: 57.67 | F10: Month-to-Month | G10: Bank Transfer | H10: 0 | I10: 5.2 | J10: 3 | K10: 2533.16 | L10: 1 | M10: Test | N10: =IF(D10<6,"<6", IF(D10<12,"6-12", IF(D10<24,"12-24",">=24"))) -> >=24 | O10: =IF(E10<30,"<30", IF(E10<60,"30-60", IF(E10<90,"60-90",">=90"))) -> 30-60 | P10: =IF(J10<4,"1-3", IF(J10<7,"4-6","7-10")) -> 1-3 | Q10: =IF(I10<20,"<20", IF(I10<40,"20-40", IF(I10<80,"40-80",">=80"))) -> <20 | R10: ="ContractType|"&F10 -> ContractType|Month-to-Month | S10: ="Tenure_Bin|"&N10 -> Tenure_Bin|>=24 | T10: ="Satis_Bin|"&P10 -> Satis_Bin|1-3 | U10: ="Monthly_Bin|"&O10 -> Monthly_Bin|30-60 | V10: ="Usage_Bin|"&Q10 -> Usage_Bin|<20 | W10: =_xlfn.XLOOKUP(R10,$AN$2:$AN$19,$AO$2:$AO$19,0) -> 3 | X10: =_xlfn.XLOOKUP(N10,$AN$2:$AN$19,$AO$2:$AO$19,0) -> 0 | Y10: =_xlfn.XLOOKUP(P10,$AN$2:$AN$19,$AO$2:$AO$19,0) -> 4 | Z10: =_xlfn.XLOOKUP(O10,$AN$2:$AN$19,$AO$2:$AO$19,0) -> 0 | AA10: =_xlfn.XLOOKUP(Q10,$AN$2:$AN$19,$AO$2:$AO$19,0) -> 2 | AB10: =SUM(W10:AA10) -> 9 | AC10: =IF(AB10>=7,"High", IF(AB10>=4,"Medium","Low")) -> High | AD10: =IF(AB10>=$AK$2,"Yes","No") -> No | AE10: =IF(AD10="Yes",1,0) -> 0 | AF10: =_xlfn.XLOOKUP(AB10, '3.3 Calibration'!$A$2:$A$14, '3.3 Calibration'!$F$2:$F$14, '3.3 Calibration'!$D$2, 1) -> 0.54545455 | AG10: =IF(AF10 >= 0.5, "Yes", "No") -> Yes | AH10: =IF(AF10>=0.6,"High", IF(AF10>=0.4,"Medium","Low")) -> Medium | AI10: =IF(AH10="High",N10,NA()) -> #N/A | AN10: 4-6 | AO10: 2
A11: 10 | B11: 40 | C11: Female | D11: 70 | E11: 94.96 | F11: Month-to-Month | G11: Credit Card | H11: 5 | I11: 21.9 | J11: 8 | K11: 6849.66 | L11: 0 | M11: Train | N11: =IF(D11<6,"<6", IF(D11<12,"6-12", IF(D11<24,"12-24",">=24"))) -> >=24 | O11: =IF(E11<30,"<30", IF(E11<60,"30-60", IF(E11<90,"60-90",">=90"))) -> >=90 | P11: =IF(J11<4,"1-3", IF(J11<7,"4-6","7-10")) -> 7-10 | Q11: =IF(I11<20,"<20", IF(I11<40,"20-40", IF(I11<80,"40-80",">=80"))) -> 20-40 | R11: ="ContractType|"&F11 -> ContractType|Month-to-Month | S11: ="Tenure_Bin|"&N11 -> Tenure_Bin|>=24 | T11: ="Satis_Bin|"&P11 -> Satis_Bin|7-10 | U11: ="Monthly_Bin|"&O11 -> Monthly_Bin|>=90 | V11: ="Usage_Bin|"&Q11 -> Usage_Bin|20-40 | W11: =_xlfn.XLOOKUP(R11,$AN$2:$AN$19,$AO$2:$AO$19,0) -> 3 | X11: =_xlfn.XLOOKUP(N11,$AN$2:$AN$19,$AO$2:$AO$19,0) -> 0 | Y11: =_xlfn.XLOOKUP(P11,$AN$2:$AN$19,$AO$2:$AO$19,0) -> 0 | Z11: =_xlfn.XLOOKUP(O11,$AN$2:$AN$19,$AO$2:$AO$19,0) -> 2 | AA11: =_xlfn.XLOOKUP(Q11,$AN$2:$AN$19,$AO$2:$AO$19,0) -> 1 | AB11: =SUM(W11:AA11) -> 6 | AC11: =IF(AB11>=7,"High", IF(AB11>=4,"Medium","Low")) -> Medium | AD11: =IF(AB11>=$AK$2,"Yes","No") -> No | AE11: =IF(AD11="Yes",1,0) -> 0 | AF11: =_xlfn.XLOOKUP(AB11, '3.3 Calibration'!$A$2:$A$14, '3.3 Calibration'!$F$2:$F$14, '3.3 Calibration'!$D$2, 1) -> 0.33333333 | AG11: =IF(AF11 >= 0.5, "Yes", "No") -> No | AH11: =IF(AF11>=0.6,"High", IF(AF11>=0.4,"Medium","Low")) -> Low | AI11: =IF(AH11="High",N11,NA()) -> #N/A | AN11: 7-10 | AO11: 0
A12: 11 | B12: 28 | C12: Male | D12: 15 | E12: 59.3 | F12: Month-to-Month | G12: Bank Transfer | H12: 1 | I12: 7.8 | J12: 8 | K12: 950.98 | L12: 0 | M12: Train | N12: =IF(D12<6,"<6", IF(D12<12,"6-12", IF(D12<24,"12-24",">=24"))) -> 12-24 | O12: =IF(E12<30,"<30", IF(E12<60,"30-60", IF(E12<90,"60-90",">=90"))) -> 30-60 | P12: =IF(J12<4,"1-3", IF(J12<7,"4-6","7-10")) -> 7-10 | Q12: =IF(I12<20,"<20", IF(I12<40,"20-40", IF(I12<80,"40-80",">=80"))) -> <20 | R12: ="ContractType|"&F12 -> ContractType|Month-to-Month | S12: ="Tenure_Bin|"&N12 -> Tenure_Bin|12-24 | T12: ="Satis_Bin|"&P12 -> Satis_Bin|7-10 | U12: ="Monthly_Bin|"&O12 -> Monthly_Bin|30-60 | V12: ="Usage_Bin|"&Q12 -> Usage_Bin|<20 | W12: =_xlfn.XLOOKUP(R12,$AN$2:$AN$19,$AO$2:$AO$19,0) -> 3 | X12: =_xlfn.XLOOKUP(N12,$AN$2:$AN$19,$AO$2:$AO$19,0) -> 1 | Y12: =_xlfn.XLOOKUP(P12,$AN$2:$AN$19,$AO$2:$AO$19,0) -> 0 | Z12: =_xlfn.XLOOKUP(O12,$AN$2:$AN$19,$AO$2:$AO$19,0) -> 0 | AA12: =_xlfn.XLOOKUP(Q12,$AN$2:$AN$19,$AO$2:$AO$19,0) -> 2 | AB12: =SUM(W12:AA12) -> 6 | AC12: =IF(AB12>=7,"High", IF(AB12>=4,"Medium","Low")) -> Medium | AD12: =IF(AB12>=$AK$2,"Yes","No") -> No | AE12: =IF(AD12="Yes",1,0) -> 0 | AF12: =_xlfn.XLOOKUP(AB12, '3.3 Calibration'!$A$2:$A$14, '3.3 Calibration'!$F$2:$F$14, '3.3 Calibration'!$D$2, 1) -> 0.33333333 | AG12: =IF(AF12 >= 0.5, "Yes", "No") -> No | AH12: =IF(AF12>=0.6,"High", IF(AF12>=0.4,"Medium","Low")) -> Low | AI12: =IF(AH12="High",N12,NA()) -> #N/A | AN12: >=90 | AO12: 2
A13: 12 | B13: 28 | C13: Female | D13: 54 | E13: 102.92 | F13: 1-Year | G13: Bank Transfer | H13: 3 | I13: 20.9 | J13: 7 | K13: 5771.64 | L13: 0 | M13: Test | N13: =IF(D13<6,"<6", IF(D13<12,"6-12", IF(D13<24,"12-24",">=24"))) -> >=24 | O13: =IF(E13<30,"<30", IF(E13<60,"30-60", IF(E13<90,"60-90",">=90"))) -> >=90 | P13: =IF(J13<4,"1-3", IF(J13<7,"4-6","7-10")) -> 7-10 | Q13: =IF(I13<20,"<20", IF(I13<40,"20-40", IF(I13<80,"40-80",">=80"))) -> 20-40 | R13: ="ContractType|"&F13 -> ContractType|1-Year | S13: ="Tenure_Bin|"&N13 -> Tenure_Bin|>=24 | T13: ="Satis_Bin|"&P13 -> Satis_Bin|7-10 | U13: ="Monthly_Bin|"&O13 -> Monthly_Bin|>=90 | V13: ="Usage_Bin|"&Q13 -> Usage_Bin|20-40 | W13: =_xlfn.XLOOKUP(R13,$AN$2:$AN$19,$AO$2:$AO$19,0) -> 1 | X13: =_xlfn.XLOOKUP(N13,$AN$2:$AN$19,$AO$2:$AO$19,0) -> 0 | Y13: =_xlfn.XLOOKUP(P13,$AN$2:$AN$19,$AO$2:$AO$19,0) -> 0 | Z13: =_xlfn.XLOOKUP(O13,$AN$2:$AN$19,$AO$2:$AO$19,0) -> 2 | AA13: =_xlfn.XLOOKUP(Q13,$AN$2:$AN$19,$AO$2:$AO$19,0) -> 1 | AB13: =SUM(W13:AA13) -> 4 | AC13: =IF(AB13>=7,"High", IF(AB13>=4,"Medium","Low")) -> Medium | AD13: =IF(AB13>=$AK$2,"Yes","No") -> No | AE13: =IF(AD13="Yes",1,0) -> 0 | AF13: =_xlfn.XLOOKUP(AB13, '3.3 Calibration'!$A$2:$A$14, '3.3 Calibration'!$F$2:$F$14, '3.3 Calibration'!$D$2, 1) -> 0.40740741 | AG13: =IF(AF13 >= 0.5, "Yes", "No") -> No | AH13: =IF(AF13>=0.6,"High", IF(AF13>=0.4,"Medium","Low")) -> Medium | AI13: =IF(AH13="High",N13,NA()) -> #N/A | AN13: 60-90 | AO13: 1
A14: 13 | B14: 41 | C14: Female | D14: 60 | E14: 76.91 | F14: Month-to-Month | G14: PayPal | H14: 0 | I14: 22.2 | J14: 6 | K14: 4549.93 | L14: 0 | M14: Train | N14: =IF(D14<6,"<6", IF(D14<12,"6-12", IF(D14<24,"12-24",">=24"))) -> >=24 | O14: =IF(E14<30,"<30", IF(E14<60,"30-60", IF(E14<90,"60-90",">=90"))) -> 60-90 | P14: =IF(J14<4,"1-3", IF(J14<7,"4-6","7-10")) -> 4-6 | Q14: =IF(I14<20,"<20", IF(I14<40,"20-40", IF(I14<80,"40-80",">=80"))) -> 20-40 | R14: ="ContractType|"&F14 -> ContractType|Month-to-Month | S14: ="Tenure_Bin|"&N14 -> Tenure_Bin|>=24 | T14: ="Satis_Bin|"&P14 -> Satis_Bin|4-6 | U14: ="Monthly_Bin|"&O14 -> Monthly_Bin|60-90 | V14: ="Usage_Bin|"&Q14 -> Usage_Bin|20-40 | W14: =_xlfn.XLOOKUP(R14,$AN$2:$AN$19,$AO$2:$AO$19,0) -> 3 | X14: =_xlfn.XLOOKUP(N14,$AN$2:$AN$19,$AO$2:$AO$19,0) -> 0 | Y14: =_xlfn.XLOOKUP(P14,$AN$2:$AN$19,$AO$2:$AO$19,0) -> 2 | Z14: =_xlfn.XLOOKUP(O14,$AN$2:$AN$19,$AO$2:$AO$19,0) -> 1 | AA14: =_xlfn.XLOOKUP(Q14,$AN$2:$AN$19,$AO$2:$AO$19,0) -> 1 | AB14: =SUM(W14:AA14) -> 7 | AC14: =IF(AB14>=7,"High", IF(AB14>=4,"Medium","Low")) -> High | AD14: =IF(AB14>=$AK$2,"Yes","No") -> No | AE14: =IF(AD14="Yes",1,0) -> 0 | AF14: =_xlfn.XLOOKUP(AB14, '3.3 Calibration'!$A$2:$A$14, '3.3 Calibration'!$F$2:$F$14, '3.3 Calibration'!$D$2, 1) -> 0.54166667 | AG14: =IF(AF14 >= 0.5, "Yes", "No") -> Yes | AH14: =IF(AF14>=0.6,"High", IF(AF14>=0.4,"Medium","Low")) -> Medium | AI14: =IF(AH14="High",N14,NA()) -> #N/A | AN14: 30-60 | AO14: 0
... A19: 18 | B19: 39 | C19: Male | D19: 68 | E19: 27.54 | F19: Month-to-Month | G19: Credit Card | H19: 2 | I19: 73.7 | J19: 7 | K19: 1852.65 | L19: 0 | M19: Train | N19: =IF(D19<6,"<6", IF(D19<12,"6-12", IF(D19<24,"12-24",">=24"))) -> >=24 | O19: =IF(E19<30,"<30", IF(E19<60,"30-60", IF(E19<90,"60-90",">=90"))) -> <30 | P19: =IF(J19<4,"1-3", IF(J19<7,"4-6","7-10")) -> 7-10 | Q19: =IF(I19<20,"<20", IF(I19<40,"20-40", IF(I19<80,"40-80",">=80"))) -> 40-80 | R19: ="ContractType|"&F19 -> ContractType|Month-to-Month | S19: ="Tenure_Bin|"&N19 -> Tenure_Bin|>=24 | T19: ="Satis_Bin|"&P19 -> Satis_Bin|7-10 | U19: ="Monthly_Bin|"&O19 -> Monthly_Bin|<30 | V19: ="Usage_Bin|"&Q19 -> Usage_Bin|40-80 | W19: =_xlfn.XLOOKUP(R19,$AN$2:$AN$19,$AO$2:$AO$19,0) -> 3 | X19: =_xlfn.XLOOKUP(N19,$AN$2:$AN$19,$AO$2:$AO$19,0) -> 0 | Y19: =_xlfn.XLOOKUP(P19,$AN$2:$AN$19,$AO$2:$AO$19,0) -> 0 | Z19: =_xlfn.XLOOKUP(O19,$AN$2:$AN$19,$AO$2:$AO$19,0) -> 0 | AA19: =_xlfn.XLOOKUP(Q19,$AN$2:$AN$19,$AO$2:$AO$19,0) -> 0 | AB19: =SUM(W19:AA19) -> 3 | AC19: =IF(AB19>=7,"High", IF(AB19>=4,"Medium","Low")) -> Low | AD19: =IF(AB19>=$AK$2,"Yes","No") -> No | AE19: =IF(AD19="Yes",1,0) -> 0 | AF19: =_xlfn.XLOOKUP(AB19, '3.3 Calibration'!$A$2:$A$14, '3.3 Calibration'!$F$2:$F$14, '3.3 Calibration'!$D$2, 1) -> 0.42105263 | AG19: =IF(AF19 >= 0.5, "Yes", "No") -> No | AH19: =IF(AF19>=0.6,"High", IF(AF19>=0.4,"Medium","Low")) -> Medium | AI19: =IF(AH19="High",N19,NA()) -> #N/A | AN19: >=80 | AO19: 0
A20: 19 | B20: 19 | C20: Female | D20: 6 | E20: 89.17 | F20: Month-to-Month | G20: PayPal | H20: 6 | I20: 14.9 | J20: 7 | K20: 566.95 | L20: 1 | M20: Train | N20: =IF(D20<6,"<6", IF(D20<12,"6-12", IF(D20<24,"12-24",">=24"))) -> 6-12 | O20: =IF(E20<30,"<30", IF(E20<60,"30-60", IF(E20<90,"60-90",">=90"))) -> 60-90 | P20: =IF(J20<4,"1-3", IF(J20<7,"4-6","7-10")) -> 7-10 | Q20: =IF(I20<20,"<20", IF(I20<40,"20-40", IF(I20<80,"40-80",">=80"))) -> <20 | R20: ="ContractType|"&F20 -> ContractType|Month-to-Month | S20: ="Tenure_Bin|"&N20 -> Tenure_Bin|6-12 | T20: ="Satis_Bin|"&P20 -> Satis_Bin|7-10 | U20: ="Monthly_Bin|"&O20 -> Monthly_Bin|60-90 | V20: ="Usage_Bin|"&Q20 -> Usage_Bin|<20 | W20: =_xlfn.XLOOKUP(R20,$AN$2:$AN$19,$AO$2:$AO$19,0) -> 3 | X20: =_xlfn.XLOOKUP(N20,$AN$2:$AN$19,$AO$2:$AO$19,0) -> 2 | Y20: =_xlfn.XLOOKUP(P20,$AN$2:$AN$19,$AO$2:$AO$19,0) -> 0 | Z20: =_xlfn.XLOOKUP(O20,$AN$2:$AN$19,$AO$2:$AO$19,0) -> 1 | AA20: =_xlfn.XLOOKUP(Q20,$AN$2:$AN$19,$AO$2:$AO$19,0) -> 2 | AB20: =SUM(W20:AA20) -> 8 | AC20: =IF(AB20>=7,"High", IF(AB20>=4,"Medium","Low")) -> High | AD20: =IF(AB20>=$AK$2,"Yes","No") -> No | AE20: =IF(AD20="Yes",1,0) -> 0 | AF20: =_xlfn.XLOOKUP(AB20, '3.3 Calibration'!$A$2:$A$14, '3.3 Calibration'!$F$2:$F$14, '3.3 Calibration'!$D$2, 1) -> 0.73684211 | AG20: =IF(AF20 >= 0.5, "Yes", "No") -> Yes | AH20: =IF(AF20>=0.6,"High", IF(AF20>=0.4,"Medium","Low")) -> High | AI20: =IF(AH20="High",N20,NA()) -> 6-12
A21: 20 | B21: 41 | C21: Male | D21: 47 | E21: 73.43 | F21: Month-to-Month | G21: Bank Transfer | H21: 3 | I21: 26.4 | J21: 3 | K21: 3673.76 | L21: 1 | M21: Train | N21: =IF(D21<6,"<6", IF(D21<12,"6-12", IF(D21<24,"12-24",">=24"))) -> >=24 | O21: =IF(E21<30,"<30", IF(E21<60,"30-60", IF(E21<90,"60-90",">=90"))) -> 60-90 | P21: =IF(J21<4,"1-3", IF(J21<7,"4-6","7-10")) -> 1-3 | Q21: =IF(I21<20,"<20", IF(I21<40,"20-40", IF(I21<80,"40-80",">=80"))) -> 20-40 | R21: ="ContractType|"&F21 -> ContractType|Month-to-Month | S21: ="Tenure_Bin|"&N21 -> Tenure_Bin|>=24 | T21: ="Satis_Bin|"&P21 -> Satis_Bin|1-3 | U21: ="Monthly_Bin|"&O21 -> Monthly_Bin|60-90 | V21: ="Usage_Bin|"&Q21 -> Usage_Bin|20-40 | W21: =_xlfn.XLOOKUP(R21,$AN$2:$AN$19,$AO$2:$AO$19,0) -> 3 | X21: =_xlfn.XLOOKUP(N21,$AN$2:$AN$19,$AO$2:$AO$19,0) -> 0 | Y21: =_xlfn.XLOOKUP(P21,$AN$2:$AN$19,$AO$2:$AO$19,0) -> 4 | Z21: =_xlfn.XLOOKUP(O21,$AN$2:$AN$19,$AO$2:$AO$19,0) -> 1 | AA21: =_xlfn.XLOOKUP(Q21,$AN$2:$AN$19,$AO$2:$AO$19,0) -> 1 | AB21: =SUM(W21:AA21) -> 9 | AC21: =IF(AB21>=7,"High", IF(AB21>=4,"Medium","Low")) -> High | AD21: =IF(AB21>=$AK$2,"Yes","No") -> No | AE21: =IF(AD21="Yes",1,0) -> 0 | AF21: =_xlfn.XLOOKUP(AB21, '3.3 Calibration'!$A$2:$A$14, '3.3 Calibration'!$F$2:$F$14, '3.3 Calibration'!$D$2, 1) -> 0.54545455 | AG21: =IF(AF21 >= 0.5, "Yes", "No") -> Yes | AH21: =IF(AF21>=0.6,"High", IF(AF21>=0.4,"Medium","Low")) -> Medium | AI21: =IF(AH21="High",N21,NA()) -> #N/A
A22: 21 | B22: 61 | C22: Female | D22: 55 | E22: 94.99 | F22: 1-Year | G22: PayPal | H22: 4 | I22: 71.8 | J22: 4 | K22: 5598.06 | L22: 0 | M22: Train | N22: =IF(D22<6,"<6", IF(D22<12,"6-12", IF(D22<24,"12-24",">=24"))) -> >=24 | O22: =IF(E22<30,"<30", IF(E22<60,"30-60", IF(E22<90,"60-90",">=90"))) -> >=90 | P22: =IF(J22<4,"1-3", IF(J22<7,"4-6","7-10")) -> 4-6 | Q22: =IF(I22<20,"<20", IF(I22<40,"20-40", IF(I22<80,"40-80",">=80"))) -> 40-80 | R22: ="ContractType|"&F22 -> ContractType|1-Year | S22: ="Tenure_Bin|"&N22 -> Tenure_Bin|>=24 | T22: ="Satis_Bin|"&P22 -> Satis_Bin|4-6 | U22: ="Monthly_Bin|"&O22 -> Monthly_Bin|>=90 | V22: ="Usage_Bin|"&Q22 -> Usage_Bin|40-80 | W22: =_xlfn.XLOOKUP(R22,$AN$2:$AN$19,$AO$2:$AO$19,0) -> 1 | X22: =_xlfn.XLOOKUP(N22,$AN$2:$AN$19,$AO$2:$AO$19,0) -> 0 | Y22: =_xlfn.XLOOKUP(P22,$AN$2:$AN$19,$AO$2:$AO$19,0) -> 2 | Z22: =_xlfn.XLOOKUP(O22,$AN$2:$AN$19,$AO$2:$AO$19,0) -> 2 | AA22: =_xlfn.XLOOKUP(Q22,$AN$2:$AN$19,$AO$2:$AO$19,0) -> 0 | AB22: =SUM(W22:AA22) -> 5 | AC22: =IF(AB22>=7,"High", IF(AB22>=4,"Medium","Low")) -> Medium | AD22: =IF(AB22>=$AK$2,"Yes","No") -> No | AE22: =IF(AD22="Yes",1,0) -> 0 | AF22: =_xlfn.XLOOKUP(AB22, '3.3 Calibration'!$A$2:$A$14, '3.3 Calibration'!$F$2:$F$14, '3.3 Calibration'!$D$2, 1) -> 0.33333333 | AG22: =IF(AF22 >= 0.5, "Yes", "No") -> No | AH22: =IF(AF22>=0.6,"High", IF(AF22>=0.4,"Medium","Low")) -> Low | AI22: =IF(AH22="High",N22,NA()) -> #N/A
A23: 22 | B23: 47 | C23: Male | D23: 40 | E23: 111.32 | F23: Month-to-Month | G23: PayPal | H23: 1 | I23: 10 | J23: 10 | K23: 4823.84 | L23: 1 | M23: Test | N23: =IF(D23<6,"<6", IF(D23<12,"6-12", IF(D23<24,"12-24",">=24"))) -> >=24 | O23: =IF(E23<30,"<30", IF(E23<60,"30-60", IF(E23<90,"60-90",">=90"))) -> >=90 | P23: =IF(J23<4,"1-3", IF(J23<7,"4-6","7-10")) -> 7-10 | Q23: =IF(I23<20,"<20", IF(I23<40,"20-40", IF(I23<80,"40-80",">=80"))) -> <20 | R23: ="ContractType|"&F23 -> ContractType|Month-to-Month | S23: ="Tenure_Bin|"&N23 -> Tenure_Bin|>=24 | T23: ="Satis_Bin|"&P23 -> Satis_Bin|7-10 | U23: ="Monthly_Bin|"&O23 -> Monthly_Bin|>=90 | V23: ="Usage_Bin|"&Q23 -> Usage_Bin|<20 | W23: =_xlfn.XLOOKUP(R23,$AN$2:$AN$19,$AO$2:$AO$19,0) -> 3 | X23: =_xlfn.XLOOKUP(N23,$AN$2:$AN$19,$AO$2:$AO$19,0) -> 0 | Y23: =_xlfn.XLOOKUP(P23,$AN$2:$AN$19,$AO$2:$AO$19,0) -> 0 | Z23: =_xlfn.XLOOKUP(O23,$AN$2:$AN$19,$AO$2:$AO$19,0) -> 2 | AA23: =_xlfn.XLOOKUP(Q23,$AN$2:$AN$19,$AO$2:$AO$19,0) -> 2 | AB23: =SUM(W23:AA23) -> 7 | AC23: =IF(AB23>=7,"High", IF(AB23>=4,"Medium","Low")) -> High | AD23: =IF(AB23>=$AK$2,"Yes","No") -> No | AE23: =IF(AD23="Yes",1,0) -> 0 | AF23: =_xlfn.XLOOKUP(AB23, '3.3 Calibration'!$A$2:$A$14, '3.3 Calibration'!$F$2:$F$14, '3.3 Calibration'!$D$2, 1) -> 0.54166667 | AG23: =IF(AF23 >= 0.5, "Yes", "No") -> Yes | AH23: =IF(AF23>=0.6,"High", IF(AF23>=0.4,"Medium","Low")) -> Medium | AI23: =IF(AH23="High",N23,NA()) -> #N/A
A24: 23 | B24: 55 | C24: Male | D24: 52 | E24: 78.51 | F24: 1-Year | G24: Credit Card | H24: 0 | I24: 51.2 | J24: 9 | K24: 4026.17 | L24: 1 | M24: Train | N24: =IF(D24<6,"<6", IF(D24<12,"6-12", IF(D24<24,"12-24",">=24"))) -> >=24 | O24: =IF(E24<30,"<30", IF(E24<60,"30-60", IF(E24<90,"60-90",">=90"))) -> 60-90 | P24: =IF(J24<4,"1-3", IF(J24<7,"4-6","7-10")) -> 7-10 | Q24: =IF(I24<20,"<20", IF(I24<40,"20-40", IF(I24<80,"40-80",">=80"))) -> 40-80 | R24: ="ContractType|"&F24 -> ContractType|1-Year | S24: ="Tenure_Bin|"&N24 -> Tenure_Bin|>=24 | T24: ="Satis_Bin|"&P24 -> Satis_Bin|7-10 | U24: ="Monthly_Bin|"&O24 -> Monthly_Bin|60-90 | V24: ="Usage_Bin|"&Q24 -> Usage_Bin|40-80 | W24: =_xlfn.XLOOKUP(R24,$AN$2:$AN$19,$AO$2:$AO$19,0) -> 1 | X24: =_xlfn.XLOOKUP(N24,$AN$2:$AN$19,$AO$2:$AO$19,0) -> 0 | Y24: =_xlfn.XLOOKUP(P24,$AN$2:$AN$19,$AO$2:$AO$19,0) -> 0 | Z24: =_xlfn.XLOOKUP(O24,$AN$2:$AN$19,$AO$2:$AO$19,0) -> 1 | AA24: =_xlfn.XLOOKUP(Q24,$AN$2:$AN$19,$AO$2:$AO$19,0) -> 0 | AB24: =SUM(W24:AA24) -> 2 | AC24: =IF(AB24>=7,"High", IF(AB24>=4,"Medium","Low")) -> Low | AD24: =IF(AB24>=$AK$2,"Yes","No") -> No | AE24: =IF(AD24="Yes",1,0) -> 0 | AF24: =_xlfn.XLOOKUP(AB24, '3.3 Calibration'!$A$2:$A$14, '3.3 Calibration'!$F$2:$F$14, '3.3 Calibration'!$D$2, 1) -> 0.6 | AG24: =IF(AF24 >= 0.5, "Yes", "No") -> Yes | AH24: =IF(AF24>=0.6,"High", IF(AF24>=0.4,"Medium","Low")) -> High | AI24: =IF(AH24="High",N24,NA()) -> >=24
A25: 24 | B25: 19 | C25: Male | D25: 16 | E25: 92.61 | F25: 2-Year | G25: Bank Transfer | H25: 1 | I25: 61.9 | J25: 6 | K25: 1428.08 | L25: 0 | M25: Train | N25: =IF(D25<6,"<6", IF(D25<12,"6-12", IF(D25<24,"12-24",">=24"))) -> 12-24 | O25: =IF(E25<30,"<30", IF(E25<60,"30-60", IF(E25<90,"60-90",">=90"))) -> >=90 | P25: =IF(J25<4,"1-3", IF(J25<7,"4-6","7-10")) -> 4-6 | Q25: =IF(I25<20,"<20", IF(I25<40,"20-40", IF(I25<80,"40-80",">=80"))) -> 40-80 | R25: ="ContractType|"&F25 -> ContractType|2-Year | S25: ="Tenure_Bin|"&N25 -> Tenure_Bin|12-24 | T25: ="Satis_Bin|"&P25 -> Satis_Bin|4-6 | U25: ="Monthly_Bin|"&O25 -> Monthly_Bin|>=90 | V25: ="Usage_Bin|"&Q25 -> Usage_Bin|40-80 | W25: =_xlfn.XLOOKUP(R25,$AN$2:$AN$19,$AO$2:$AO$19,0) -> 0 | X25: =_xlfn.XLOOKUP(N25,$AN$2:$AN$19,$AO$2:$AO$19,0) -> 1 | Y25: =_xlfn.XLOOKUP(P25,$AN$2:$AN$19,$AO$2:$AO$19,0) -> 2 | Z25: =_xlfn.XLOOKUP(O25,$AN$2:$AN$19,$AO$2:$AO$19,0) -> 2 | AA25: =_xlfn.XLOOKUP(Q25,$AN$2:$AN$19,$AO$2:$AO$19,0) -> 0 | AB25: =SUM(W25:AA25) -> 5 | AC25: =IF(AB25>=7,"High", IF(AB25>=4,"Medium","Low")) -> Medium | AD25: =IF(AB25>=$AK$2,"Yes","No") -> No | AE25: =IF(AD25="Yes",1,0) -> 0 | AF25: =_xlfn.XLOOKUP(AB25, '3.3 Calibration'!$A$2:$A$14, '3.3 Calibration'!$F$2:$F$14, '3.3 Calibration'!$D$2, 1) -> 0.33333333 | AG25: =IF(AF25 >= 0.5, "Yes", "No") -> No | AH25: =IF(AF25>=0.6,"High", IF(AF25>=0.4,"Medium","Low")) -> Low | AI25: =IF(AH25="High",N25,NA()) -> #N/A
A26: 25 | B26: 38 | C26: Female | D26: 13 | E26: 95.71 | F26: Month-to-Month | G26: PayPal | H26: 1 | I26: 62.2 | J26: 5 | K26: 1264.68 | L26: 0 | M26: Test | N26: =IF(D26<6,"<6", IF(D26<12,"6-12", IF(D26<24,"12-24",">=24"))) -> 12-24 | O26: =IF(E26<30,"<30", IF(E26<60,"30-60", IF(E26<90,"60-90",">=90"))) -> >=90 | P26: =IF(J26<4,"1-3", IF(J26<7,"4-6","7-10")) -> 4-6 | Q26: =IF(I26<20,"<20", IF(I26<40,"20-40", IF(I26<80,"40-80",">=80"))) -> 40-80 | R26: ="ContractType|"&F26 -> ContractType|Month-to-Month | S26: ="Tenure_Bin|"&N26 -> Tenure_Bin|12-24 | T26: ="Satis_Bin|"&P26 -> Satis_Bin|4-6 | U26: ="Monthly_Bin|"&O26 -> Monthly_Bin|>=90 | V26: ="Usage_Bin|"&Q26 -> Usage_Bin|40-80 | W26: =_xlfn.XLOOKUP(R26,$AN$2:$AN$19,$AO$2:$AO$19,0) -> 3 | X26: =_xlfn.XLOOKUP(N26,$AN$2:$AN$19,$AO$2:$AO$19,0) -> 1 | Y26: =_xlfn.XLOOKUP(P26,$AN$2:$AN$19,$AO$2:$AO$19,0) -> 2 | Z26: =_xlfn.XLOOKUP(O26,$AN$2:$AN$19,$AO$2:$AO$19,0) -> 2 | AA26: =_xlfn.XLOOKUP(Q26,$AN$2:$AN$19,$AO$2:$AO$19,0) -> 0 | AB26: =SUM(W26:AA26) -> 8 | AC26: =IF(AB26>=7,"High", IF(AB26>=4,"Medium","Low")) -> High | AD26: =IF(AB26>=$AK$2,"Yes","No") -> No | AE26: =IF(AD26="Yes",1,0) -> 0 | AF26: =_xlfn.XLOOKUP(AB26, '3.3 Calibration'!$A$2:$A$14, '3.3 Calibration'!$F$2:$F$14, '3.3 Calibration'!$D$2, 1) -> 0.73684211 | AG26: =IF(AF26 >= 0.5, "Yes", "No") -> Yes | AH26: =IF(AF26>=0.6,"High", IF(AF26>=0.4,"Medium","Low")) -> High | AI26: =IF(AH26="High",N26,NA()) -> 12-24
A27: 26 | B27: 50 | C27: Female | D27: 30 | E27: 57.79 | F27: Month-to-Month | G27: Bank Transfer | H27: 4 | I27: 7.2 | J27: 3 | K27: 1689.03 | L27: 0 | M27: Test | N27: =IF(D27<6,"<6", IF(D27<12,"6-12", IF(D27<24,"12-24",">=24"))) -> >=24 | O27: =IF(E27<30,"<30", IF(E27<60,"30-60", IF(E27<90,"60-90",">=90"))) -> 30-60 | P27: =IF(J27<4,"1-3", IF(J27<7,"4-6","7-10")) -> 1-3 | Q27: =IF(I27<20,"<20", IF(I27<40,"20-40", IF(I27<80,"40-80",">=80"))) -> <20 | R27: ="ContractType|"&F27 -> ContractType|Month-to-Month | S27: ="Tenure_Bin|"&N27 -> Tenure_Bin|>=24 | T27: ="Satis_Bin|"&P27 -> Satis_Bin|1-3 | U27: ="Monthly_Bin|"&O27 -> Monthly_Bin|30-60 | V27: ="Usage_Bin|"&Q27 -> Usage_Bin|<20 | W27: =_xlfn.XLOOKUP(R27,$AN$2:$AN$19,$AO$2:$AO$19,0) -> 3 | X27: =_xlfn.XLOOKUP(N27,$AN$2:$AN$19,$AO$2:$AO$19,0) -> 0 | Y27: =_xlfn.XLOOKUP(P27,$AN$2:$AN$19,$AO$2:$AO$19,0) -> 4 | Z27: =_xlfn.XLOOKUP(O27,$AN$2:$AN$19,$AO$2:$AO$19,0) -> 0 | AA27: =_xlfn.XLOOKUP(Q27,$AN$2:$AN$19,$AO$2:$AO$19,0) -> 2 | AB27: =SUM(W27:AA27) -> 9 | AC27: =IF(AB27>=7,"High", IF(AB27>=4,"Medium","Low")) -> High | AD27: =IF(AB27>=$AK$2,"Yes","No") -> No | AE27: =IF(AD27="Yes",1,0) -> 0 | AF27: =_xlfn.XLOOKUP(AB27, '3.3 Calibration'!$A$2:$A$14, '3.3 Calibration'!$F$2:$F$14, '3.3 Calibration'!$D$2, 1) -> 0.54545455 | AG27: =IF(AF27 >= 0.5, "Yes", "No") -> Yes | AH27: =IF(AF27>=0.6,"High", IF(AF27>=0.4,"Medium","Low")) -> Medium | AI27: =IF(AH27="High",N27,NA()) -> #N/A
A28: 27 | B28: 29 | C28: Male | D28: 19 | E28: 44.11 | F28: Month-to-Month | G28: PayPal | H28: 1 | I28: 35.6 | J28: 9 | K28: 855.03 | L28: 0 | M28: Train | N28: =IF(D28<6,"<6", IF(D28<12,"6-12", IF(D28<24,"12-24",">=24"))) -> 12-24 | O28: =IF(E28<30,"<30", IF(E28<60,"30-60", IF(E28<90,"60-90",">=90"))) -> 30-60 | P28: =IF(J28<4,"1-3", IF(J28<7,"4-6","7-10")) -> 7-10 | Q28: =IF(I28<20,"<20", IF(I28<40,"20-40", IF(I28<80,"40-80",">=80"))) -> 20-40 | R28: ="ContractType|"&F28 -> ContractType|Month-to-Month | S28: ="Tenure_Bin|"&N28 -> Tenure_Bin|12-24 | T28: ="Satis_Bin|"&P28 -> Satis_Bin|7-10 | U28: ="Monthly_Bin|"&O28 -> Monthly_Bin|30-60 | V28: ="Usage_Bin|"&Q28 -> Usage_Bin|20-40 | W28: =_xlfn.XLOOKUP(R28,$AN$2:$AN$19,$AO$2:$AO$19,0) -> 3 | X28: =_xlfn.XLOOKUP(N28,$AN$2:$AN$19,$AO$2:$AO$19,0) -> 1 | Y28: =_xlfn.XLOOKUP(P28,$AN$2:$AN$19,$AO$2:$AO$19,0) -> 0 | Z28: =_xlfn.XLOOKUP(O28,$AN$2:$AN$19,$AO$2:$AO$19,0) -> 0 | AA28: =_xlfn.XLOOKUP(Q28,$AN$2:$AN$19,$AO$2:$AO$19,0) -> 1 | AB28: =SUM(W28:AA28) -> 5 | AC28: =IF(AB28>=7,"High", IF(AB28>=4,"Medium","Low")) -> Medium | AD28: =IF(AB28>=$AK$2,"Yes","No") -> No | AE28: =IF(AD28="Yes",1,0) -> 0 | AF28: =_xlfn.XLOOKUP(AB28, '3.3 Calibration'!$A$2:$A$14, '3.3 Calibration'!$F$2:$F$14, '3.3 Calibration'!$D$2, 1) -> 0.33333333 | AG28: =IF(AF28 >= 0.5, "Yes", "No") -> No | AH28: =IF(AF28>=0.6,"High", IF(AF28>=0.4,"Medium","Low")) -> Low | AI28: =IF(AH28="High",N28,NA()) -> #N/A
A29: 28 | B29: 39 | C29: Female | D29: 17 | E29: 40.5 | F29: Month-to-Month | G29: PayPal | H29: 2 | I29: 65.5 | J29: 5 | K29: 716.81 | L29: 0 | M29: Train | N29: =IF(D29<6,"<6", IF(D29<12,"6-12", IF(D29<24,"12-24",">=24"))) -> 12-24 | O29: =IF(E29<30,"<30", IF(E29<60,"30-60", IF(E29<90,"60-90",">=90"))) -> 30-60 | P29: =IF(J29<4,"1-3", IF(J29<7,"4-6","7-10")) -> 4-6 | Q29: =IF(I29<20,"<20", IF(I29<40,"20-40", IF(I29<80,"40-80",">=80"))) -> 40-80 | R29: ="ContractType|"&F29 -> ContractType|Month-to-Month | S29: ="Tenure_Bin|"&N29 -> Tenure_Bin|12-24 | T29: ="Satis_Bin|"&P29 -> Satis_Bin|4-6 | U29: ="Monthly_Bin|"&O29 -> Monthly_Bin|30-60 | V29: ="Usage_Bin|"&Q29 -> Usage_Bin|40-80 | W29: =_xlfn.XLOOKUP(R29,$AN$2:$AN$19,$AO$2:$AO$19,0) -> 3 | X29: =_xlfn.XLOOKUP(N29,$AN$2:$AN$19,$AO$2:$AO$19,0) -> 1 | Y29: =_xlfn.XLOOKUP(P29,$AN$2:$AN$19,$AO$2:$AO$19,0) -> 2 | Z29: =_xlfn.XLOOKUP(O29,$AN$2:$AN$19,$AO$2:$AO$19,0) -> 0 | AA29: =_xlfn.XLOOKUP(Q29,$AN$2:$AN$19,$AO$2:$AO$19,0) -> 0 | AB29: =SUM(W29:AA29) -> 6 | AC29: =IF(AB29>=7,"High", IF(AB29>=4,"Medium","Low")) -> Medium | AD29: =IF(AB29>=$AK$2,"Yes","No") -> No | AE29: =IF(AD29="Yes",1,0) -> 0 | AF29: =_xlfn.XLOOKUP(AB29, '3.3 Calibration'!$A$2:$A$14, '3.3 Calibration'!$F$2:$F$14, '3.3 Calibration'!$D$2, 1) -> 0.33333333 | AG29: =IF(AF29 >= 0.5, "Yes", "No") -> No | AH29: =IF(AF29>=0.6,"High", IF(AF29>=0.4,"Medium","Low")) -> Low | AI29: =IF(AH29="High",N29,NA()) -> #N/A
A30: 29 | B30: 61 | C30: Male | D30: 63 | E30: 45.14 | F30: 1-Year | G30: Bank Transfer | H30: 1 | I30: 19.2 | J30: 5 | K30: 2950.98 | L30: 0 | M30: Train | N30: =IF(D30<6,"<6", IF(D30<12,"6-12", IF(D30<24,"12-24",">=24"))) -> >=24 | O30: =IF(E30<30,"<30", IF(E30<60,"30-60", IF(E30<90,"60-90",">=90"))) -> 30-60 | P30: =IF(J30<4,"1-3", IF(J30<7,"4-6","7-10")) -> 4-6 | Q30: =IF(I30<20,"<20", IF(I30<40,"20-40", IF(I30<80,"40-80",">=80"))) -> <20 | R30: ="ContractType|"&F30 -> ContractType|1-Year | S30: ="Tenure_Bin|"&N30 -> Tenure_Bin|>=24 | T30: ="Satis_Bin|"&P30 -> Satis_Bin|4-6 | U30: ="Monthly_Bin|"&O30 -> Monthly_Bin|30-60 | V30: ="Usage_Bin|"&Q30 -> Usage_Bin|<20 | W30: =_xlfn.XLOOKUP(R30,$AN$2:$AN$19,$AO$2:$AO$19,0) -> 1 | X30: =_xlfn.XLOOKUP(N30,$AN$2:$AN$19,$AO$2:$AO$19,0) -> 0 | Y30: =_xlfn.XLOOKUP(P30,$AN$2:$AN$19,$AO$2:$AO$19,0) -> 2 | Z30: =_xlfn.XLOOKUP(O30,$AN$2:$AN$19,$AO$2:$AO$19,0) -> 0 | AA30: =_xlfn.XLOOKUP(Q30,$AN$2:$AN$19,$AO$2:$AO$19,0) -> 2 | AB30: =SUM(W30:AA30) -> 5 | AC30: =IF(AB30>=7,"High", IF(AB30>=4,"Medium","Low")) -> Medium | AD30: =IF(AB30>=$AK$2,"Yes","No") -> No | AE30: =IF(AD30="Yes",1,0) -> 0 | AF30: =_xlfn.XLOOKUP(AB30, '3.3 Calibration'!$A$2:$A$14, '3.3 Calibration'!$F$2:$F$14, '3.3 Calibration'!$D$2, 1) -> 0.33333333 | AG30: =IF(AF30 >= 0.5, "Yes", "No") -> No | AH30: =IF(AF30>=0.6,"High", IF(AF30>=0.4,"Medium","Low")) -> Low | AI30: =IF(AH30="High",N30,NA()) -> #N/A
A31: 30 | B31: 42 | C31: Male | D31: 19 | E31: 47.47 | F31: 2-Year | G31: PayPal | H31: 1 | I31: 71.1 | J31: 4 | K31: 879.3 | L31: 1 | M31: Train | N31: =IF(D31<6,"<6", IF(D31<12,"6-12", IF(D31<24,"12-24",">=24"))) -> 12-24 | O31: =IF(E31<30,"<30", IF(E31<60,"30-60", IF(E31<90,"60-90",">=90"))) -> 30-60 | P31: =IF(J31<4,"1-3", IF(J31<7,"4-6","7-10")) -> 4-6 | Q31: =IF(I31<20,"<20", IF(I31<40,"20-40", IF(I31<80,"40-80",">=80"))) -> 40-80 | R31: ="ContractType|"&F31 -> ContractType|2-Year | S31: ="Tenure_Bin|"&N31 -> Tenure_Bin|12-24 | T31: ="Satis_Bin|"&P31 -> Satis_Bin|4-6 | U31: ="Monthly_Bin|"&O31 -> Monthly_Bin|30-60 | V31: ="Usage_Bin|"&Q31 -> Usage_Bin|40-80 | W31: =_xlfn.XLOOKUP(R31,$AN$2:$AN$19,$AO$2:$AO$19,0) -> 0 | X31: =_xlfn.XLOOKUP(N31,$AN$2:$AN$19,$AO$2:$AO$19,0) -> 1 | Y31: =_xlfn.XLOOKUP(P31,$AN$2:$AN$19,$AO$2:$AO$19,0) -> 2 | Z31: =_xlfn.XLOOKUP(O31,$AN$2:$AN$19,$AO$2:$AO$19,0) -> 0 | AA31: =_xlfn.XLOOKUP(Q31,$AN$2:$AN$19,$AO$2:$AO$19,0) -> 0 | AB31: =SUM(W31:AA31) -> 3 | AC31: =IF(AB31>=7,"High", IF(AB31>=4,"Medium","Low")) -> Low | AD31: =IF(AB31>=$AK$2,"Yes","No") -> No | AE31: =IF(AD31="Yes",1,0) -> 0 | AF31: =_xlfn.XLOOKUP(AB31, '3.3 Calibration'!$A$2:$A$14, '3.3 Calibration'!$F$2:$F$14, '3.3 Calibration'!$D$2, 1) -> 0.42105263 | AG31: =IF(AF31 >= 0.5, "Yes", "No") -> No | AH31: =IF(AF31>=0.6,"High", IF(AF31>=0.4,"Medium","Low")) -> Medium | AI31: =IF(AH31="High",N31,NA()) -> #N/A
... A251: 250 | B251: 69 | C251: Male | D251: 66 | E251: 95.24 | F251: 1-Year | G251: Bank Transfer | H251: 5 | I251: 46.4 | J251: 9 | K251: 6712.45 | L251: 0 | M251: Test | N251: =IF(D251<6,"<6", IF(D251<12,"6-12", IF(D251<24,"12-24",">=24"))) -> >=24 | O251: =IF(E251<30,"<30", IF(E251<60,"30-60", IF(E251<90,"60-90",">=90"))) -> >=90 | P251: =IF(J251<4,"1-3", IF(J251<7,"4-6","7-10")) -> 7-10 | Q251: =IF(I251<20,"<20", IF(I251<40,"20-40", IF(I251<80,"40-80",">=80"))) -> 40-80 | R251: ="ContractType|"&F251 -> ContractType|1-Year | S251: ="Tenure_Bin|"&N251 -> Tenure_Bin|>=24 | T251: ="Satis_Bin|"&P251 -> Satis_Bin|7-10 | U251: ="Monthly_Bin|"&O251 -> Monthly_Bin|>=90 | V251: ="Usage_Bin|"&Q251 -> Usage_Bin|40-80 | W251: =_xlfn.XLOOKUP(R251,$AN$2:$AN$19,$AO$2:$AO$19,0) -> 1 | X251: =_xlfn.XLOOKUP(N251,$AN$2:$AN$19,$AO$2:$AO$19,0) -> 0 | Y251: =_xlfn.XLOOKUP(P251,$AN$2:$AN$19,$AO$2:$AO$19,0) -> 0 | Z251: =_xlfn.XLOOKUP(O251,$AN$2:$AN$19,$AO$2:$AO$19,0) -> 2 | AA251: =_xlfn.XLOOKUP(Q251,$AN$2:$AN$19,$AO$2:$AO$19,0) -> 0 | AB251: =SUM(W251:AA251) -> 3 | AC251: =IF(AB251>=7,"High", IF(AB251>=4,"Medium","Low")) -> Low | AD251: =IF(AB251>=$AK$2,"Yes","No") -> No | AE251: =IF(AD251="Yes",1,0) -> 0 | AF251: =_xlfn.XLOOKUP(AB251, '3.3 Calibration'!$A$2:$A$14, '3.3 Calibration'!$F$2:$F$14, '3.3 Calibration'!$D$2, 1) -> 0.42105263 | AG251: =IF(AF251 >= 0.5, "Yes", "No") -> No | AH251: =IF(AF251>=0.6,"High", IF(AF251>=0.4,"Medium","Low")) -> Medium | AI251: =IF(AH251="High",N251,NA()) -> #N/A
AG252: =IF(AF252 >= 0.5, "Yes", "No") -> No | AH252: =IF(AF252>=0.6,"High", IF(AF252>=0.4,"Medium","Low")) -> Low | AI252: =IF(AH252="High",N252,NA()) -> #N/A
AG253: =IF(AF253 >= 0.5, "Yes", "No") -> No | AH253: =IF(AF253>=0.6,"High", IF(AF253>=0.4,"Medium","Low")) -> Low | AI253: =IF(AH253="High",N253,NA()) -> #N/A
AG254: =IF(AF254 >= 0.5, "Yes", "No") -> No | AH254: =IF(AF254>=0.6,"High", IF(AF254>=0.4,"Medium","Low")) -> Low | AI254: =IF(AH254="High",N254,NA()) -> #N/A
AG255: =IF(AF255 >= 0.5, "Yes", "No") -> No | AH255: =IF(AF255>=0.6,"High", IF(AF255>=0.4,"Medium","Low")) -> Low | AI255: =IF(AH255="High",N255,NA()) -> #N/A
AG256: =IF(AF256 >= 0.5, "Yes", "No") -> No | AH256: =IF(AF256>=0.6,"High", IF(AF256>=0.4,"Medium","Low")) -> Low | AI256: =IF(AH256="High",N256,NA()) -> #N/A
AG257: =IF(AF257 >= 0.5, "Yes", "No") -> No | AH257: =IF(AF257>=0.6,"High", IF(AF257>=0.4,"Medium","Low")) -> Low | AI257: =IF(AH257="High",N257,NA()) -> #N/A
AG258: =IF(AF258 >= 0.5, "Yes", "No") -> No | AH258: =IF(AF258>=0.6,"High", IF(AF258>=0.4,"Medium","Low")) -> Low | AI258: =IF(AH258="High",N258,NA()) -> #N/A
AG259: =IF(AF259 >= 0.5, "Yes", "No") -> No | AH259: =IF(AF259>=0.6,"High", IF(AF259>=0.4,"Medium","Low")) -> Low | AI259: =IF(AH259="High",N259,NA()) -> #N/A
AG260: =IF(AF260 >= 0.5, "Yes", "No") -> No | AH260: =IF(AF260>=0.6,"High", IF(AF260>=0.4,"Medium","Low")) -> Low | AI260: =IF(AH260="High",N260,NA()) -> #N/A
AG261: =IF(AF261 >= 0.5, "Yes", "No") -> No | AH261: =IF(AF261>=0.6,"High", IF(AF261>=0.4,"Medium","Low")) -> Low | AI261: =IF(AH261="High",N261,NA()) -> #N/A
AG262: =IF(AF262 >= 0.5, "Yes", "No") -> No | AH262: =IF(AF262>=0.6,"High", IF(AF262>=0.4,"Medium","Low")) -> Low | AI262: =IF(AH262="High",N262,NA()) -> #N/A
AG263: =IF(AF263 >= 0.5, "Yes", "No") -> No | AH263: =IF(AF263>=0.6,"High", IF(AF263>=0.4,"Medium","Low")) -> Low | AI263: =IF(AH263="High",N263,NA()) -> #N/A
...

Sheet 2.1 Regression
A1: Age | B1: Tenure | C1: MonthlyCharges | D1: SupportTickets | E1: ServiceUsage | F1: SatisfactionScore | G1: TotalSpend | H1: Churn
A2: 56 | B2: 58 | C2: 28.27 | D2: 2 | E2: 52.7 | F2: 6 | G2: 1614.09 | H2: 1
A3: 69 | B3: 63 | C3: 107.67 | D3: 1 | E3: 16.8 | F3: 1 | G3: 6505.15 | H3: 1 | J3: SUMMARY OUTPUT
A4: 46 | B4: 62 | C4: 75.16 | D4: 1 | E4: 41.6 | F4: 5 | G4: 4646.87 | H4: 0
A5: 32 | B5: 22 | C5: 36.48 | D5: 1 | E5: 66.1 | F5: 3 | G5: 814.95 | H5: 1 | J5: Regression Statistics
A6: 60 | B6: 58 | C6: 61.13 | D6: 3 | E6: 79.1 | F6: 1 | G6: 3222 | H6: 1 | J6: Multiple R | K6: 0.30281581
A7: 25 | B7: 58 | C7: 97.76 | D7: 2 | E7: 25.6 | F7: 4 | G7: 5242.56 | H7: 1 | J7: R Square | K7: 0.091697415
A8: 38 | B8: 49 | C8: 68.04 | D8: 2 | E8: 18.1 | F8: 2 | G8: 3373.06 | H8: 1 | J8: Adjusted R Square | K8: 0.0654242
A9: 56 | B9: 52 | C9: 118.53 | D9: 3 | E9: 68 | F9: 2 | G9: 5970.23 | H9: 0 | J9: Standard Error | K9: 0.48357691
A10: 36 | B10: 42 | C10: 57.67 | D10: 0 | E10: 5.2 | F10: 3 | G10: 2533.16 | H10: 1 | J10: Observations | K10: 250
A11: 40 | B11: 70 | C11: 94.96 | D11: 5 | E11: 21.9 | F11: 8 | G11: 6849.66 | H11: 0
A12: 28 | B12: 15 | C12: 59.3 | D12: 1 | E12: 7.8 | F12: 8 | G12: 950.98 | H12: 0 | J12: ANOVA
A13: 28 | B13: 54 | C13: 102.92 | D13: 3 | E13: 20.9 | F13: 7 | G13: 5771.64 | H13: 0 | K13: df | L13: SS | M13: MS | N13: F | O13: Significance F
A14: 41 | B14: 60 | C14: 76.91 | D14: 0 | E14: 22.2 | F14: 6 | G14: 4549.93 | H14: 0 | J14: Regression | K14: 7 | L14: 5.7131157 | M14: 0.81615939 | N14: 3.4901482 | O14: 0.001387096
A15: 53 | B15: 8 | C15: 26.35 | D15: 1 | E15: 41.8 | F15: 9 | G15: 218.09 | H15: 1 | J15: Residual | K15: 242 | L15: 56.590884 | M15: 0.23384663
A16: 57 | B16: 53 | C16: 23.68 | D16: 1 | E16: 43.2 | F16: 4 | G16: 1198.66 | H16: 0 | J16: Total | K16: 249 | L16: 62.304
A17: 41 | B17: 60 | C17: 33.39 | D17: 3 | E17: 88.1 | F17: 1 | G17: 1925.79 | H17: 1
A18: 20 | B18: 5 | C18: 21.37 | D18: 3 | E18: 53.5 | F18: 8 | G18: 113.03 | H18: 0 | K18: Coefficients | L18: Standard Error | M18: t Stat | N18: P-value | O18: Lower 95% | P18: Upper 95% | Q18: Lower 95.0% | R18: Upper 95.0%
A19: 39 | B19: 68 | C19: 27.54 | D19: 2 | E19: 73.7 | F19: 7 | G19: 1852.65 | H19: 0 | J19: Intercept | K19: 0.602082 | L19: 0.19975633 | M19: 3.0140823 | N19: 0.0028517499 | O19: 0.20859896 | P19: 0.99556503 | Q19: 0.20859896 | R19: 0.99556503
A20: 19 | B20: 6 | C20: 89.17 | D20: 6 | E20: 14.9 | F20: 7 | G20: 566.95 | H20: 1 | J20: Age | K20: -0.0011302138 | L20: 0.0020599581 | M20: -0.54865865 | N20: 0.58374555 | O20: -0.0051879505 | P20: 0.0029275228 | Q20: -0.0051879505 | R20: 0.0029275228
A21: 41 | B21: 47 | C21: 73.43 | D21: 3 | E21: 26.4 | F21: 3 | G21: 3673.76 | H21: 1 | J21: Tenure | K21: 0.0028360258 | L21: 0.0039532711 | M21: 0.71738713 | N21: 0.47382713 | O21: -0.0049511875 | P21: 0.010623239 | Q21: -0.0049511875 | R21: 0.010623239
A22: 61 | B22: 55 | C22: 94.99 | D22: 4 | E22: 71.8 | F22: 4 | G22: 5598.06 | H22: 0 | J22: MonthlyCharges | K22: 0.0018064253 | L22: 0.0021306508 | M22: 0.84782795 | N22: 0.39737155 | O22: -0.0023905629 | P22: 0.0060034135 | Q22: -0.0023905629 | R22: 0.0060034135
A23: 47 | B23: 40 | C23: 111.32 | D23: 1 | E23: 10 | F23: 10 | G23: 4823.84 | H23: 1 | J23: SupportTickets | K23: -0.0077821511 | L23: 0.023086421 | M23: -0.33708781 | N23: 0.73634287 | O23: -0.053258133 | P23: 0.03769383 | Q23: -0.053258133 | R23: 0.03769383
A24: 55 | B24: 52 | C24: 78.51 | D24: 0 | E24: 51.2 | F24: 9 | G24: 4026.17 | H24: 1 | J24: ServiceUsage | K24: 0.0019819795 | L24: 0.0011169201 | M24: 1.7745042 | N24: 0.077236963 | O24: -0.00021814668 | P24: 0.0041821057 | Q24: -0.00021814668 | R24: 0.0041821057
A25: 19 | B25: 16 | C25: 92.61 | D25: 1 | E25: 61.9 | F25: 6 | G25: 1428.08 | H25: 0 | J25: SatisfactionScore | K25: -0.04407049 | L25: 0.01089867 | M25: -4.0436577 | N25: 7.0776475e-05 | O25: -0.065538854 | P25: -0.022602125 | Q25: -0.065538854 | R25: -0.022602125
A26: 38 | B26: 13 | C26: 95.71 | D26: 1 | E26: 62.2 | F26: 5 | G26: 1264.68 | H26: 0 | J26: TotalSpend | K26: -6.3935698e-05 | L26: 5.1823786e-05 | M26: -1.2337134 | N26: 0.21850658 | O26: -0.00016601898 | P26: 3.8147579e-05 | Q26: -0.00016601898 | R26: 3.8147579e-05
A27: 50 | B27: 30 | C27: 57.79 | D27: 4 | E27: 7.2 | F27: 3 | G27: 1689.03 | H27: 0
A28: 29 | B28: 19 | C28: 44.11 | D28: 1 | E28: 35.6 | F28: 9 | G28: 855.03 | H28: 0
A29: 39 | B29: 17 | C29: 40.5 | D29: 2 | E29: 65.5 | F29: 5 | G29: 716.81 | H29: 0
A30: 61 | B30: 63 | C30: 45.14 | D30: 1 | E30: 19.2 | F30: 5 | G30: 2950.98 | H30: 0 | K30: Age | L30: Tenure | M30: MonthlyCharges | N30: SupportTickets | O30: ServiceUsage | P30: SatisfactionScore | Q30: TotalSpend | R30: Churn
A31: 42 | B31: 19 | C31: 47.47 | D31: 1 | E31: 71.1 | F31: 4 | G31: 879.3 | H31: 1 | J31: Age | K31: 1
A32: 66 | B32: 58 | C32: 40.72 | D32: 2 | E32: 75.9 | F32: 4 | G32: 2204.4 | H32: 1 | J32: Tenure | K32: 0.14689271 | L32: 1
A33: 44 | B33: 55 | C33: 107.82 | D33: 2 | E33: 98.3 | F33: 1 | G33: 5847.71 | H33: 0 | J33: MonthlyCharges | K33: 0.053954113 | L33: -0.0061242558 | M33: 1
A34: 59 | B34: 62 | C34: 95.7 | D34: 4 | E34: 24.9 | F34: 7 | G34: 5509.27 | H34: 0 | J34: SupportTickets | K34: -0.079744087 | L34: 0.18350683 | M34: 0.088981326 | N34: 1
A35: 45 | B35: 23 | C35: 24.69 | D35: 5 | E35: 83.4 | F35: 9 | G35: 612.17 | H35: 1 | J35: ServiceUsage | K35: 0.12177667 | L35: 0.0086782237 | M35: -0.073505396 | N35: 0.048312037 | O35: 1
A36: 33 | B36: 9 | C36: 46.87 | D36: 0 | E36: 54.4 | F36: 3 | G36: 408.83 | H36: 1 | J36: SatisfactionScore | K36: -0.01934497 | L36: 0.092591523 | M36: -0.087628608 | N36: 0.025787339 | O36: -0.0027606005 | P36: 1
A37: 32 | B37: 12 | C37: 22.22 | D37: 1 | E37: 40.5 | F37: 2 | G37: 248.21 | H37: 0 | J37: TotalSpend | K37: 0.13928475 | L37: 0.78187454 | M37: 0.52987461 | N37: 0.21223924 | O37: -0.05183902 | P37: 0.029912521 | Q37: 1
A38: 64 | B38: 1 | C38: 69.82 | D38: 1 | E38: 16.6 | F38: 3 | G38: 63.19 | H38: 0 | J38: Churn | K38: -0.024970367 | L38: -0.10016428 | M38: -0.014899159 | N38: -0.039512828 | O38: 0.11168543 | P38: -0.25523745 | Q38: -0.11437044 | R38: 1
A39: 68 | B39: 58 | C39: 67.62 | D39: 3 | E39: 74.9 | F39: 1 | G39: 4036.34 | H39: 0
A40: 61 | B40: 1 | C40: 103.14 | D40: 2 | E40: 27.4 | F40: 6 | G40: 105.96 | H40: 1
...

Sheet 2.2 Pivot Churn rate
A3: Row Labels | B3: Sum of Churn | C3: % | F3: 1-Year | G3: 0.25 | J3: Bank Transfer | K3: 0.32
A4: Bank Transfer | B4: 38 | C4: =38/GETPIVOTDATA("Churn",$A$3) -> 0.3220339 | F4: 2-Year | G4: 0.12 | J4: Credit Card | K4: 0.36
A5: Credit Card | B5: 43 | C5: =GETPIVOTDATA("Churn",$A$3,"PaymentMethod","Credit Card")/GETPIVOTDATA("Churn",$A$3) -> 0.36440678 | F5: Month to Month | G5: 0.63 | J5: Paypal | K5: 0.31
A6: PayPal | B6: 37 | C6: =GETPIVOTDATA("Churn",$A$3,"PaymentMethod","PayPal")/GETPIVOTDATA("Churn",$A$3) -> 0.31355932
A7: Grand Total | B7: 118

Sheet 3.1 Classifer
A1: CustomerID | B1: Age | C1: Gender | D1: Tenure | E1: MonthlyCharges | F1: ContractType | G1: PaymentMethod | H1: SupportTickets | I1: ServiceUsage | J1: SatisfactionScore | K1: TotalSpend | L1: Churn | M1: Split | N1: Tenure_Bin | O1: Monthly_Bin | P1: Satis_Bin | Q1: Usage_Bin | R1: Contract_Key | S1: Tenure_Key | T1: Satis_Key | U1: Monthly_Key | V1: Usage_Key | W1: Contract_Pts | X1: Tenure_Pts | Y1: Satis_Pts | Z1: Monthly_Pts | AA1: Usage_Pts | AB1: TotalScore | AC1: PredictedClass | AD1: PredictedChurn | AE1: PredFlag | AF1: PredictedProb | AG1: PredictedChurn | AH1: RiskTier
A2: 2 | B2: 69 | C2: Female | D2: 63 | E2: 107.67 | F2: 1-Year | G2: Credit Card | H2: 1 | I2: 16.8 | J2: 1 | K2: 6505.15 | L2: 1 | M2: Train | N2: >=24 | O2: >=90 | P2: 1-3 | Q2: <20 | R2: ContractType|1-Year | S2: Tenure_Bin|>=24 | T2: Satis_Bin|1-3 | U2: Monthly_Bin|>=90 | V2: Usage_Bin|<20 | W2: 1 | X2: 0 | Y2: 4 | Z2: 2 | AA2: 2 | AB2: 9 | AC2: High | AD2: No | AE2: 0 | AF2: 0.54545455 | AG2: Yes | AH2: Medium
